Workbook
Name Mã_số_ca: #REF!
Name Vật_Tư: #REF!
Name Bang_dulieu: #REF!
Name Số_Lượng: #REF!
Name Ngày: #REF!
Name Tên_con_vật: #REF!
Name Gia_chủ: #REF!
Name Sđt: #REF!
Name Mã_Hàng: #REF!
Name Bệnh_lý: #REF!
Name Địa_chỉ: #REF!
Name Đơn_giá: #REF!

Sheet BC Thang
B1: CSDL khách hàng | E1: Số tiền CBC | F1: =SUMIFS(L4:L3085, I4:I3085, "CBC") -> 4070 | G1: Số ca CBC | I1: =countifs(I4:I3086,"CBC") -> 21 | L1: Total | M1: =O1-N1 -> 119414 | N1: =SUMIFS(M4:M3342, N4:N3342, "CK petshop thầy") -> 2816 | O1: =SUM(M4:M2974) -> 122230 | Q1: =SUM(Q4:Q2974) -> 122230
A3: Ngày | B3: MS ca | C3: SDT | D3: Gia chủ | E3: Địa chỉ | F3: Loài | G3: Tên thú | H3: TL(Kg) | I3: Bệnh lý/Thủ thuật/thuốc | J3: Phí thu | K3: Số lượng | L3: Thành tiền | M3: Tổng thu | N3: Người thu | O3: Chú ý | P3: Ngày ra viện | Q3: Tổng thu Tuần
A4: 45962 | D4: khách lẻ | E4: =vlookup($C4,CSDL!$A:$E,3,0) -> #N/A | F4: =vlookup($C4,CSDL!$A:$E,4,0) -> #N/A | G4: =vlookup($C4,CSDL!$A:$E,5,0) -> #N/A | I4: Tẩy giun nhỏ | J4: 20 | K4: 3 | L4: =K4*J4 -> 60 | M4: 60 | N4: Thầy
D5: khách lẻ | E5: =vlookup($C5,CSDL!$A:$E,3,0) -> #N/A | F5: =vlookup($C5,CSDL!$A:$E,4,0) -> #N/A | G5: =vlookup($C5,CSDL!$A:$E,5,0) -> #N/A | I5: Thuốc bán | J5: 30 | K5: 7 | L5: =K5*J5 -> 210 | M5: 250 | N5: CK thầy | O5: 1/11 - Nguyen Phan Ha My ct
D6: =vlookup($C6,CSDL!$A:$E,2,0) -> #N/A | E6: =vlookup($C6,CSDL!$A:$E,3,0) -> #N/A | F6: =vlookup($C6,CSDL!$A:$E,4,0) -> #N/A | G6: =vlookup($C6,CSDL!$A:$E,5,0) -> #N/A | I6: Tẩy giun nhỏ | J6: 40 | K6: 1 | L6: =K6*J6 -> 40
D7: khách lẻ | I7: Tẩy giun lớn | J7: 50 | K7: 1 | L7: =K7*J7 -> 50 | M7: 50 | N7: CK thầy | O7: 1/11 - Tran Thi Ny ct
B8: 1170 | C8: 0833 555 733 | D8: =vlookup($C8,CSDL!$A:$E,2,0) -> ANh Trí | E8: =vlookup($C8,CSDL!$A:$E,3,0) -> An NInh | F8: =vlookup($C8,CSDL!$A:$E,4,0) -> n | G8: =vlookup($C8,CSDL!$A:$E,5,0) -> Miu | I8: Chích thuốc nhỏ | J8: 120 | K8: 1 | L8: =K8*J8 -> 120 | M8: 120 | N8: CK thầy | O8: 1/11 - Minh Tri ct
B9: 1171 | C9: 0935 403 717 | D9: =vlookup($C9,CSDL!$A:$E,2,0) | E9: =vlookup($C9,CSDL!$A:$E,3,0) -> Ngõ 29/245A Bùi Thị Xuân | F9: =vlookup($C9,CSDL!$A:$E,4,0) -> Mèo | G9: =vlookup($C9,CSDL!$A:$E,5,0) | I9: Petshop | J9: =170+39 -> 209 | K9: 1 | L9: =K9*J9 -> 209 | M9: 219 | N9: CK petshop thầy | O9: 269k - 1/11 - Ho Vu Nhat ct
B10: 1171 | D10: =vlookup($C10,CSDL!$A:$E,2,0) -> #N/A | E10: =vlookup($C10,CSDL!$A:$E,3,0) -> #N/A | F10: =vlookup($C10,CSDL!$A:$E,4,0) -> #N/A | G10: =vlookup($C10,CSDL!$A:$E,5,0) -> #N/A | I10: Tẩy giun nhỏ | J10: 50 | K10: 1 | L10: =K10*J10 -> 50 | M10: 50 | N10: CK thầy
D11: khách lẻ | E11: =vlookup($C11,CSDL!$A:$E,3,0) -> #N/A | F11: =vlookup($C11,CSDL!$A:$E,4,0) -> #N/A | G11: =vlookup($C11,CSDL!$A:$E,5,0) -> #N/A | I11: Petshop | J11: 50 | K11: 1 | L11: =K11*J11 -> 50 | M11: 50 | N11: CK petshop thầy | O11: 1/11 - Tran Duc Anh Quan ct
B12: 1172 | C12: 0372 033 490 | D12: =vlookup($C12,CSDL!$A:$E,2,0) -> Em Thọ | E12: =vlookup($C12,CSDL!$A:$E,3,0) | F12: =vlookup($C12,CSDL!$A:$E,4,0) | G12: =vlookup($C12,CSDL!$A:$E,5,0) | I12: Lưu trú nhỏ | J12: 150 | K12: 3 | L12: =K12*J12 -> 450 | M12: 450 | N12: CK thầy | O12: 4/11 - Tran Dinh Huu Tho
A13: 45963 | B13: 1101 | C13: 0903 565 648 | D13: =vlookup($C13,CSDL!$A:$E,2,0) -> Sư Cô Thanh Nhã | E13: =vlookup($C13,CSDL!$A:$E,3,0) -> Quảng Trị | F13: =vlookup($C13,CSDL!$A:$E,4,0) -> Chó | G13: Bảo Bảo | L13: =K13*J13 -> 0 | M13: 4000 | N13: CK thầy | O13: 2/11 - Phan Thi Thanh Phuong ct
B14: 1101 | D14: =vlookup($C14,CSDL!$A:$E,2,0) -> #N/A | E14: =vlookup($C14,CSDL!$A:$E,3,0) -> #N/A | F14: =vlookup($C14,CSDL!$A:$E,4,0) -> #N/A | G14: =vlookup($C14,CSDL!$A:$E,5,0) -> #N/A | L14: =K14*J14 -> 0 | M14: 300 | N14: Ánh
B15: 1161 | C15: 0935 919 137 | D15: =vlookup($C15,CSDL!$A:$E,2,0) -> Anh Cường | E15: =vlookup($C15,CSDL!$A:$E,3,0) -> Hương Hồ | F15: =vlookup($C15,CSDL!$A:$E,4,0) -> Chó | G15: =vlookup($C15,CSDL!$A:$E,5,0) -> Nâu | L15: =K15*J15 -> 0 | M15: 640 | N15: CK thầy | O15: 2/11 - Bui Van Cuong
B16: 1173 | C16: 0903 584 535 | D16: =vlookup($C16,CSDL!$A:$E,2,0) -> Chị Ánh Nguyệt | E16: =vlookup($C16,CSDL!$A:$E,3,0) -> 40 Lý Thái Tổ | F16: =vlookup($C16,CSDL!$A:$E,4,0) -> Mèo | G16: =vlookup($C16,CSDL!$A:$E,5,0) -> Sumo | I16: Thuốc bán | J16: 35 | K16: 1 | L16: =K16*J16 -> 35 | M16: =2571-36 -> 2535 | N16: CK thầy | O16: 2571k - 2/11 - Tran Thi Anh Nguyet ct
B17: 1173 | D17: =vlookup($C17,CSDL!$A:$E,2,0) -> #N/A | E17: =vlookup($C17,CSDL!$A:$E,3,0) -> #N/A | F17: =vlookup($C17,CSDL!$A:$E,4,0) -> #N/A | G17: =vlookup($C17,CSDL!$A:$E,5,0) -> #N/A | I17: Lưu trú nhỏ | J17: 120 | K17: 3 | L17: =K17*J17 -> 360 | M17: 36 | N17: CK petshop thầy
B18: 1173 | D18: =vlookup($C18,CSDL!$A:$E,2,0) -> #N/A | E18: =vlookup($C18,CSDL!$A:$E,3,0) -> #N/A | F18: =vlookup($C18,CSDL!$A:$E,4,0) -> #N/A | G18: =vlookup($C18,CSDL!$A:$E,5,0) -> #N/A | I18: CBC | J18: 150 | K18: 1 | L18: =K18*J18 -> 150
B19: 1173 | D19: =vlookup($C19,CSDL!$A:$E,2,0) -> #N/A | E19: =vlookup($C19,CSDL!$A:$E,3,0) -> #N/A | F19: =vlookup($C19,CSDL!$A:$E,4,0) -> #N/A | G19: =vlookup($C19,CSDL!$A:$E,5,0) -> #N/A | I19: Sinh hóa máu | J19: 300 | K19: 1 | L19: =K19*J19 -> 300
B20: 1173 | D20: =vlookup($C20,CSDL!$A:$E,2,0) -> #N/A | E20: =vlookup($C20,CSDL!$A:$E,3,0) -> #N/A | F20: =vlookup($C20,CSDL!$A:$E,4,0) -> #N/A | G20: =vlookup($C20,CSDL!$A:$E,5,0) -> #N/A | I20: Thuốc FIP tiêm | J20: 1700 | K20: 1 | L20: =K20*J20 -> 1700
B21: 1173 | D21: =vlookup($C21,CSDL!$A:$E,2,0) -> #N/A | E21: =vlookup($C21,CSDL!$A:$E,3,0) -> #N/A | F21: =vlookup($C21,CSDL!$A:$E,4,0) -> #N/A | G21: =vlookup($C21,CSDL!$A:$E,5,0) -> #N/A | I21: Petshop | J21: 36 | K21: 1 | L21: =K21*J21 -> 36
A22: 45965 | B22: 1174 | C22: 0905 563 662 | D22: =vlookup($C22,CSDL!$A:$E,2,0) -> Anh Dũng | E22: =vlookup($C22,CSDL!$A:$E,3,0) -> 57 Lê Duẩn | F22: =vlookup($C22,CSDL!$A:$E,4,0) -> chó | G22: =vlookup($C22,CSDL!$A:$E,5,0) -> Ken | I22: Vaccine 7b chó | J22: 180 | K22: 1 | L22: =K22*J22 -> 180 | M22: 320 | N22: Ánh
B23: 1174 | D23: =vlookup($C23,CSDL!$A:$E,2,0) -> #N/A | E23: =vlookup($C23,CSDL!$A:$E,3,0) -> #N/A | F23: =vlookup($C23,CSDL!$A:$E,4,0) -> #N/A | G23: =vlookup($C23,CSDL!$A:$E,5,0) -> #N/A | I23: Chích thuốc nhỏ | J23: 100 | K23: 1 | L23: =K23*J23 -> 100
B24: 1174 | D24: =vlookup($C24,CSDL!$A:$E,2,0) -> #N/A | E24: =vlookup($C24,CSDL!$A:$E,3,0) -> #N/A | F24: =vlookup($C24,CSDL!$A:$E,4,0) -> #N/A | G24: =vlookup($C24,CSDL!$A:$E,5,0) -> #N/A | I24: Tẩy giun nhỏ | J24: 40 | K24: 1 | L24: =K24*J24 -> 40
D25: khách lẻ | I25: Men tiêu hoá | J25: 10 | K25: 1 | L25: =K25*J25 -> 10 | M25: 10 | N25: CK thầy | O25: 4/11- Huong Giang ct
B26: 1175 | C26: 0888 671 489 | D26: =vlookup($C26,CSDL!$A:$E,2,0) | E26: =vlookup($C26,CSDL!$A:$E,3,0) | F26: =vlookup($C26,CSDL!$A:$E,4,0) | G26: =vlookup($C26,CSDL!$A:$E,5,0) | I26: Hỏa Táng | J26: 1450 | K26: 1 | L26: =K26*J26 -> 1450 | M26: 1500 | N26: CK thầy | O26: 4/11 - Nguyen Ngoc Quy ct
B27: 1175 | D27: =vlookup($C27,CSDL!$A:$E,2,0) -> #N/A | E27: =vlookup($C27,CSDL!$A:$E,3,0) -> #N/A | F27: =vlookup($C27,CSDL!$A:$E,4,0) -> #N/A | G27: =vlookup($C27,CSDL!$A:$E,5,0) -> #N/A | L27: =K27*J27 -> 0 | M27: -50
B28: 1176 | C28: 0905 733 786 | D28: =vlookup($C28,CSDL!$A:$E,2,0) -> Em Bảo Uyên | E28: =vlookup($C28,CSDL!$A:$E,3,0) -> 180 Lý Nam Đế | F28: =vlookup($C28,CSDL!$A:$E,4,0) -> Chó | G28: =vlookup($C28,CSDL!$A:$E,5,0) -> Lạc | I28: Lưu điều trị nhỏ | J28: 150 | K28: 1 | L28: =K28*J28 -> 150 | M28: 150 | N28: CK thầy | O28: 29/11 - Bao Uyen ct
B29: 1177 | C29: 0934 769 696 | D29: =vlookup($C29,CSDL!$A:$E,2,0) -> Anh Vũ | E29: =vlookup($C29,CSDL!$A:$E,3,0) -> 25 Lương Quán | F29: =vlookup($C29,CSDL!$A:$E,4,0) -> Chó | G29: =vlookup($C29,CSDL!$A:$E,5,0) -> Đen | I29: Lưu trú nhỏ | J29: 200 | L29: =K29*J29 -> 0 | M29: 1000 | N29: CK thầy | O29: 4/11 - Bui Van Vu ct
B30: 1177 | M30: 3500 | N30: CK thầy | O30: 23/11 - Bui Van Vu ct
B31: 1178 | C31: 0796 052 617 | D31: =vlookup($C31,CSDL!$A:$E,2,0) -> Chị Thuý | E31: =vlookup($C31,CSDL!$A:$E,3,0) -> Lô E9 Hương Bình | F31: =vlookup($C31,CSDL!$A:$E,4,0) -> chó | I31: Chích thuốc nhỏ | J31: 150 | K31: 2 | L31: =K31*J31 -> 300 | M31: 150 | N31: Trà
B32: 1178 | D32: =vlookup($C32,CSDL!$A:$E,2,0) -> #N/A | E32: =vlookup($C32,CSDL!$A:$E,3,0) -> #N/A | F32: =vlookup($C32,CSDL!$A:$E,4,0) -> #N/A | G32: =vlookup($C32,CSDL!$A:$E,5,0) -> #N/A | I32: Tẩy giun nhỏ | J32: 10 | K32: 1 | L32: =K32*J32 -> 10 | M32: 285 | N32: CK thầy | O32: 7/11 - Diem Thuy ct
B33: 1178 | D33: =vlookup($C33,CSDL!$A:$E,2,0) -> #N/A | E33: =vlookup($C33,CSDL!$A:$E,3,0) -> #N/A | F33: =vlookup($C33,CSDL!$A:$E,4,0) -> #N/A | G33: =vlookup($C33,CSDL!$A:$E,5,0) -> #N/A | I33: Thuốc bán | J33: 25 | K33: 5 | L33: =K33*J33 -> 125
B34: 1179 | C34: 0944 208 167 | D34: =vlookup($C34,CSDL!$A:$E,2,0) -> Em Duy | E34: =vlookup($C34,CSDL!$A:$E,3,0) | F34: =vlookup($C34,CSDL!$A:$E,4,0) -> Chó | G34: =vlookup($C34,CSDL!$A:$E,5,0) -> Quýt | I34: Lưu điều trị nhỏ | J34: 150 | K34: 2 | L34: =K34*J34 -> 300 | M34: 500 | N34: CK thầy | O34: 4/11 - Truong Dien Huong ct
B35: 1179 | D35: =vlookup($C35,CSDL!$A:$E,2,0) -> #N/A | E35: =vlookup($C35,CSDL!$A:$E,3,0) -> #N/A | F35: =vlookup($C35,CSDL!$A:$E,4,0) -> #N/A | G35: =vlookup($C35,CSDL!$A:$E,5,0) -> #N/A | I35: Diệt ve Hantox | J35: 50 | K35: 1 | L35: =K35*J35 -> 50 | M35: -150
D36: Ngọc Anh | E36: =vlookup($C36,CSDL!$A:$E,3,0) -> #N/A | F36: =vlookup($C36,CSDL!$A:$E,4,0) -> #N/A | G36: =vlookup($C36,CSDL!$A:$E,5,0) -> #N/A | I36: Vaccine 7b chó | J36: 180 | K36: 1 | L36: =K36*J36 -> 180 | M36: 180 | N36: CK thầy | O36: 4/11 - Ngoc Anh - hẹn 25/11 tiêm 7b + dại
D37: khách lẻ | E37: =vlookup($C37,CSDL!$A:$E,3,0) -> #N/A | F37: =vlookup($C37,CSDL!$A:$E,4,0) -> #N/A | G37: =vlookup($C37,CSDL!$A:$E,5,0) -> #N/A | I37: Petshop | J37: 70 | K37: 1 | L37: =K37*J37 -> 70 | M37: 70 | N37: CK petshop thầy | O37: 4/11 - Vo Thi Kim Hang ct
B38: 1180 | C38: 0349 978 213 | D38: =vlookup($C38,CSDL!$A:$E,2,0) -> Diễm Quỳnh | E38: =vlookup($C38,CSDL!$A:$E,3,0) -> 2/5 Nguyễn Phúc thái | F38: Mèo | G38: Chó | H38: 2 | I38: FPV- | J38: 150 | K38: 1 | L38: =K38*J38 -> 150 | M38: 500 | N38: Trà
B39: 1180 | D39: =vlookup($C39,CSDL!$A:$E,2,0) -> #N/A | E39: =vlookup($C39,CSDL!$A:$E,3,0) -> #N/A | F39: =vlookup($C39,CSDL!$A:$E,4,0) -> #N/A | G39: =vlookup($C39,CSDL!$A:$E,5,0) -> #N/A | I39: Lưu điều trị nhỏ | J39: 150 | K39: 4 | L39: =K39*J39 -> 600 | M39: 400 | N39: CK thầy | O39: 7/11 - Tran tan Anh Khoa
B40: 1180 | D40: =vlookup($C40,CSDL!$A:$E,2,0) -> #N/A | E40: =vlookup($C40,CSDL!$A:$E,3,0) -> #N/A | F40: =vlookup($C40,CSDL!$A:$E,4,0) -> #N/A | G40: =vlookup($C40,CSDL!$A:$E,5,0) -> #N/A | I40: Thuốc bán | J40: 30 | K40: 5 | L40: =K40*J40 -> 150
B41: 1181 | C41: 0903 565 648 | D41: =vlookup($C41,CSDL!$A:$E,2,0) -> Sư Cô Thanh Nhã | E41: =vlookup($C41,CSDL!$A:$E,3,0) -> Quảng Trị | F41: =vlookup($C41,CSDL!$A:$E,4,0) -> Chó | G41: Bảo | I41: Thuốc bán | J41: 35 | K41: 7 | L41: =K41*J41 -> 245 | M41: 315 | N41: CK thầy | O41: 4/11 - Phan Thi Thanh Phuong ct
...

Sheet CSDL
A1: =IFERROR(__xludf.DUMMYFUNCTION("importrange(""https://docs.google.com/spreadsheets/d/1s8yEsKu3EMT_o1gfopKM8FAT3y4j4rENhR6GH49MzHc/edit#gid=0"",""CSDL khach hang!A:E"")"),"")
A3: =IFERROR(__xludf.DUMMYFUNCTION("""COMPUTED_VALUE"""),"0914 125 773") -> 0914 125 773 | B3: =IFERROR(__xludf.DUMMYFUNCTION("""COMPUTED_VALUE"""),"Bác Quân") -> Bác Quân | C3: =IFERROR(__xludf.DUMMYFUNCTION("""COMPUTED_VALUE"""),"ngõ 69 k131 Trần Phú") -> ngõ 69 k131 Trần Phú | D3: =IFERROR(__xludf.DUMMYFUNCTION("""COMPUTED_VALUE"""),"chó") -> chó | E3: =IFERROR(__xludf.DUMMYFUNCTION("""COMPUTED_VALUE"""),"sóc") -> sóc
A4: =IFERROR(__xludf.DUMMYFUNCTION("""COMPUTED_VALUE"""),"0368 142 234") -> 0368 142 234 | B4: =IFERROR(__xludf.DUMMYFUNCTION("""COMPUTED_VALUE"""),"Chị Yến") -> Chị Yến | C4: =IFERROR(__xludf.DUMMYFUNCTION("""COMPUTED_VALUE"""),"C 1 chung cư Trường An") -> C 1 chung cư Trường An | D4: =IFERROR(__xludf.DUMMYFUNCTION("""COMPUTED_VALUE"""),"mèo") -> mèo
A5: =IFERROR(__xludf.DUMMYFUNCTION("""COMPUTED_VALUE"""),"0829 448 009") -> 0829 448 009 | B5: =IFERROR(__xludf.DUMMYFUNCTION("""COMPUTED_VALUE"""),"anh Huy") -> anh Huy | C5: =IFERROR(__xludf.DUMMYFUNCTION("""COMPUTED_VALUE"""),"30/6 Tôn Thất Tùng") -> 30/6 Tôn Thất Tùng | D5: =IFERROR(__xludf.DUMMYFUNCTION("""COMPUTED_VALUE"""),"mèo") -> mèo
A6: =IFERROR(__xludf.DUMMYFUNCTION("""COMPUTED_VALUE"""),"0819 038 058") -> 0819 038 058 | B6: =IFERROR(__xludf.DUMMYFUNCTION("""COMPUTED_VALUE"""),"em Bình") -> em Bình | D6: =IFERROR(__xludf.DUMMYFUNCTION("""COMPUTED_VALUE"""),"mèo") -> mèo | E6: =IFERROR(__xludf.DUMMYFUNCTION("""COMPUTED_VALUE"""),"bu") -> bu
A7: =IFERROR(__xludf.DUMMYFUNCTION("""COMPUTED_VALUE"""),"0775 527 554") -> 0775 527 554 | B7: =IFERROR(__xludf.DUMMYFUNCTION("""COMPUTED_VALUE"""),"chị Thúy") -> chị Thúy | C7: =IFERROR(__xludf.DUMMYFUNCTION("""COMPUTED_VALUE"""),"9/62 Nguyễn gia Thiều") -> 9/62 Nguyễn gia Thiều | D7: =IFERROR(__xludf.DUMMYFUNCTION("""COMPUTED_VALUE"""),"chó") -> chó | E7: =IFERROR(__xludf.DUMMYFUNCTION("""COMPUTED_VALUE"""),"lu") -> lu
A8: =IFERROR(__xludf.DUMMYFUNCTION("""COMPUTED_VALUE"""),"0973 067 961") -> 0973 067 961 | B8: =IFERROR(__xludf.DUMMYFUNCTION("""COMPUTED_VALUE"""),"Em Hoàng Lê Quân") -> Em Hoàng Lê Quân | C8: =IFERROR(__xludf.DUMMYFUNCTION("""COMPUTED_VALUE"""),"198 Phan chu Trinh") -> 198 Phan chu Trinh | D8: =IFERROR(__xludf.DUMMYFUNCTION("""COMPUTED_VALUE"""),"mèo") -> mèo | E8: =IFERROR(__xludf.DUMMYFUNCTION("""COMPUTED_VALUE"""),"ú") -> ú
A9: =IFERROR(__xludf.DUMMYFUNCTION("""COMPUTED_VALUE"""),"0905 817 329") -> 0905 817 329 | B9: =IFERROR(__xludf.DUMMYFUNCTION("""COMPUTED_VALUE"""),"Anh Phúc") -> Anh Phúc | C9: =IFERROR(__xludf.DUMMYFUNCTION("""COMPUTED_VALUE"""),"98 Minh Mạng") -> 98 Minh Mạng | D9: =IFERROR(__xludf.DUMMYFUNCTION("""COMPUTED_VALUE"""),"chó") -> chó | E9: =IFERROR(__xludf.DUMMYFUNCTION("""COMPUTED_VALUE"""),"nâu") -> nâu
A10: =IFERROR(__xludf.DUMMYFUNCTION("""COMPUTED_VALUE"""),"0772 407 863") -> 0772 407 863 | B10: =IFERROR(__xludf.DUMMYFUNCTION("""COMPUTED_VALUE"""),"Anh Hoàng") -> Anh Hoàng | D10: =IFERROR(__xludf.DUMMYFUNCTION("""COMPUTED_VALUE"""),"chó") -> chó | E10: =IFERROR(__xludf.DUMMYFUNCTION("""COMPUTED_VALUE"""),"phú quốc lai") -> phú quốc lai
A11: =IFERROR(__xludf.DUMMYFUNCTION("""COMPUTED_VALUE"""),"0385 748 754") -> 0385 748 754 | B11: =IFERROR(__xludf.DUMMYFUNCTION("""COMPUTED_VALUE"""),"Cô Dung") -> Cô Dung | C11: =IFERROR(__xludf.DUMMYFUNCTION("""COMPUTED_VALUE"""),"Trần phú") -> Trần phú | D11: =IFERROR(__xludf.DUMMYFUNCTION("""COMPUTED_VALUE"""),"chó") -> chó | E11: =IFERROR(__xludf.DUMMYFUNCTION("""COMPUTED_VALUE"""),"lisa") -> lisa
A12: =IFERROR(__xludf.DUMMYFUNCTION("""COMPUTED_VALUE"""),"0966 857 262") -> 0966 857 262 | B12: =IFERROR(__xludf.DUMMYFUNCTION("""COMPUTED_VALUE"""),"Chị Na") -> Chị Na | C12: =IFERROR(__xludf.DUMMYFUNCTION("""COMPUTED_VALUE"""),"k131 Trần Phú") -> k131 Trần Phú | D12: =IFERROR(__xludf.DUMMYFUNCTION("""COMPUTED_VALUE"""),"mèo") -> mèo | E12: =IFERROR(__xludf.DUMMYFUNCTION("""COMPUTED_VALUE"""),"gạo") -> gạo
A13: =IFERROR(__xludf.DUMMYFUNCTION("""COMPUTED_VALUE"""),"0708 730 799") -> 0708 730 799 | B13: =IFERROR(__xludf.DUMMYFUNCTION("""COMPUTED_VALUE"""),"em Nhung") -> em Nhung | D13: =IFERROR(__xludf.DUMMYFUNCTION("""COMPUTED_VALUE"""),"mèo") -> mèo | E13: =IFERROR(__xludf.DUMMYFUNCTION("""COMPUTED_VALUE"""),"tít") -> tít
A14: =IFERROR(__xludf.DUMMYFUNCTION("""COMPUTED_VALUE"""),"0985 511 469") -> 0985 511 469 | B14: =IFERROR(__xludf.DUMMYFUNCTION("""COMPUTED_VALUE"""),"chị Vy") -> chị Vy | C14: =IFERROR(__xludf.DUMMYFUNCTION("""COMPUTED_VALUE"""),"phong điền") -> phong điền | D14: =IFERROR(__xludf.DUMMYFUNCTION("""COMPUTED_VALUE"""),"chó") -> chó | E14: =IFERROR(__xludf.DUMMYFUNCTION("""COMPUTED_VALUE"""),"su") -> su
A15: =IFERROR(__xludf.DUMMYFUNCTION("""COMPUTED_VALUE"""),"0981 576 817") -> 0981 576 817 | B15: =IFERROR(__xludf.DUMMYFUNCTION("""COMPUTED_VALUE"""),"em Tuấn Anh") -> em Tuấn Anh | C15: =IFERROR(__xludf.DUMMYFUNCTION("""COMPUTED_VALUE"""),"63 xuân Diệu") -> 63 xuân Diệu | D15: =IFERROR(__xludf.DUMMYFUNCTION("""COMPUTED_VALUE"""),"mèo") -> mèo | E15: =IFERROR(__xludf.DUMMYFUNCTION("""COMPUTED_VALUE"""),"cơm") -> cơm
A16: =IFERROR(__xludf.DUMMYFUNCTION("""COMPUTED_VALUE"""),"0935 201 515") -> 0935 201 515 | B16: =IFERROR(__xludf.DUMMYFUNCTION("""COMPUTED_VALUE"""),"em Ngọc-con anh Mỹ") -> em Ngọc-con anh Mỹ | C16: =IFERROR(__xludf.DUMMYFUNCTION("""COMPUTED_VALUE"""),"vũ ngọc phan/nguyễn huệ") -> vũ ngọc phan/nguyễn huệ | D16: =IFERROR(__xludf.DUMMYFUNCTION("""COMPUTED_VALUE"""),"chó") -> chó | E16: =IFERROR(__xludf.DUMMYFUNCTION("""COMPUTED_VALUE"""),"đốm") -> đốm
A17: =IFERROR(__xludf.DUMMYFUNCTION("""COMPUTED_VALUE"""),"0395 530 843") -> 0395 530 843 | B17: =IFERROR(__xludf.DUMMYFUNCTION("""COMPUTED_VALUE"""),"Dì Trâm- bác Toàn ") -> Dì Trâm- bác Toàn | C17: =IFERROR(__xludf.DUMMYFUNCTION("""COMPUTED_VALUE"""),"8/16 Đoàn Hữu Trưng") -> 8/16 Đoàn Hữu Trưng | D17: =IFERROR(__xludf.DUMMYFUNCTION("""COMPUTED_VALUE"""),"mèo ") -> mèo | E17: =IFERROR(__xludf.DUMMYFUNCTION("""COMPUTED_VALUE"""),"bao/đùi gà") -> bao/đùi gà
A18: =IFERROR(__xludf.DUMMYFUNCTION("""COMPUTED_VALUE"""),"0393 221 804") -> 0393 221 804 | B18: =IFERROR(__xludf.DUMMYFUNCTION("""COMPUTED_VALUE"""),"em Mỹ Ngọc") -> em Mỹ Ngọc | C18: =IFERROR(__xludf.DUMMYFUNCTION("""COMPUTED_VALUE"""),"18/10 Nguyễn Trường Tộ") -> 18/10 Nguyễn Trường Tộ | D18: =IFERROR(__xludf.DUMMYFUNCTION("""COMPUTED_VALUE"""),"mèo") -> mèo | E18: =IFERROR(__xludf.DUMMYFUNCTION("""COMPUTED_VALUE"""),"chocolate") -> chocolate
A19: =IFERROR(__xludf.DUMMYFUNCTION("""COMPUTED_VALUE"""),"0795 326 380") -> 0795 326 380 | B19: =IFERROR(__xludf.DUMMYFUNCTION("""COMPUTED_VALUE"""),"em Hồ Thị Phương Thảo") -> em Hồ Thị Phương Thảo | C19: =IFERROR(__xludf.DUMMYFUNCTION("""COMPUTED_VALUE"""),"75 Hồ Đắc Di") -> 75 Hồ Đắc Di | D19: =IFERROR(__xludf.DUMMYFUNCTION("""COMPUTED_VALUE"""),"mèo") -> mèo | E19: =IFERROR(__xludf.DUMMYFUNCTION("""COMPUTED_VALUE"""),"Bạch Tuộc") -> Bạch Tuộc
A20: =IFERROR(__xludf.DUMMYFUNCTION("""COMPUTED_VALUE"""),"0367 150 406") -> 0367 150 406 | B20: =IFERROR(__xludf.DUMMYFUNCTION("""COMPUTED_VALUE"""),"Chú Dũng") -> Chú Dũng | C20: =IFERROR(__xludf.DUMMYFUNCTION("""COMPUTED_VALUE"""),"k227 Trần Phú") -> k227 Trần Phú | D20: =IFERROR(__xludf.DUMMYFUNCTION("""COMPUTED_VALUE"""),"chó") -> chó | E20: =IFERROR(__xludf.DUMMYFUNCTION("""COMPUTED_VALUE"""),"12kg") -> 12kg
A21: =IFERROR(__xludf.DUMMYFUNCTION("""COMPUTED_VALUE"""),"0915 061 282") -> 0915 061 282 | B21: =IFERROR(__xludf.DUMMYFUNCTION("""COMPUTED_VALUE"""),"Anh Trung- c Hà Chung") -> Anh Trung- c Hà Chung | C21: =IFERROR(__xludf.DUMMYFUNCTION("""COMPUTED_VALUE"""),"25/250 Phan Bội Châu") -> 25/250 Phan Bội Châu | D21: =IFERROR(__xludf.DUMMYFUNCTION("""COMPUTED_VALUE"""),"chó") -> chó | E21: =IFERROR(__xludf.DUMMYFUNCTION("""COMPUTED_VALUE"""),"bà điên") -> bà điên
A22: =IFERROR(__xludf.DUMMYFUNCTION("""COMPUTED_VALUE"""),"0914 219 823") -> 0914 219 823 | B22: =IFERROR(__xludf.DUMMYFUNCTION("""COMPUTED_VALUE"""),"Anh Huy") -> Anh Huy | C22: =IFERROR(__xludf.DUMMYFUNCTION("""COMPUTED_VALUE"""),"k1 Bảo Quốc") -> k1 Bảo Quốc | D22: =IFERROR(__xludf.DUMMYFUNCTION("""COMPUTED_VALUE"""),"vẹt") -> vẹt
A23: =IFERROR(__xludf.DUMMYFUNCTION("""COMPUTED_VALUE"""),"0343 787 737") -> 0343 787 737 | B23: =IFERROR(__xludf.DUMMYFUNCTION("""COMPUTED_VALUE"""),"Anh Tài") -> Anh Tài | C23: =IFERROR(__xludf.DUMMYFUNCTION("""COMPUTED_VALUE"""),"78B Phú Bài") -> 78B Phú Bài | D23: =IFERROR(__xludf.DUMMYFUNCTION("""COMPUTED_VALUE"""),"Mèo") -> Mèo
A24: =IFERROR(__xludf.DUMMYFUNCTION("""COMPUTED_VALUE"""),"0907 804 763") -> 0907 804 763 | B24: =IFERROR(__xludf.DUMMYFUNCTION("""COMPUTED_VALUE"""),"Anh Hồ Ngọc Tuấn ") -> Anh Hồ Ngọc Tuấn | C24: =IFERROR(__xludf.DUMMYFUNCTION("""COMPUTED_VALUE"""),"Vỹ Dạ") -> Vỹ Dạ | D24: =IFERROR(__xludf.DUMMYFUNCTION("""COMPUTED_VALUE"""),"chó") -> chó | E24: =IFERROR(__xludf.DUMMYFUNCTION("""COMPUTED_VALUE"""),"đậu hũ thúi") -> đậu hũ thúi
A25: =IFERROR(__xludf.DUMMYFUNCTION("""COMPUTED_VALUE"""),"0911 004 431") -> 0911 004 431 | B25: =IFERROR(__xludf.DUMMYFUNCTION("""COMPUTED_VALUE"""),"Em Lan Anh") -> Em Lan Anh | C25: =IFERROR(__xludf.DUMMYFUNCTION("""COMPUTED_VALUE"""),"k56 Đào Tấn") -> k56 Đào Tấn | D25: =IFERROR(__xludf.DUMMYFUNCTION("""COMPUTED_VALUE"""),"mèo") -> mèo
A26: =IFERROR(__xludf.DUMMYFUNCTION("""COMPUTED_VALUE"""),"0375 954 665") -> 0375 954 665 | B26: =IFERROR(__xludf.DUMMYFUNCTION("""COMPUTED_VALUE"""),"Anh Nghĩa") -> Anh Nghĩa | C26: =IFERROR(__xludf.DUMMYFUNCTION("""COMPUTED_VALUE"""),"193 Phan Đăng Lưu") -> 193 Phan Đăng Lưu | D26: =IFERROR(__xludf.DUMMYFUNCTION("""COMPUTED_VALUE"""),"chó") -> chó
A27: =IFERROR(__xludf.DUMMYFUNCTION("""COMPUTED_VALUE"""),"0914 145 264") -> 0914 145 264 | B27: =IFERROR(__xludf.DUMMYFUNCTION("""COMPUTED_VALUE"""),"Bác Quốc") -> Bác Quốc | C27: =IFERROR(__xludf.DUMMYFUNCTION("""COMPUTED_VALUE"""),"29/2/44 lê Ngô Cát") -> 29/2/44 lê Ngô Cát | D27: =IFERROR(__xludf.DUMMYFUNCTION("""COMPUTED_VALUE"""),"chó") -> chó
A28: =IFERROR(__xludf.DUMMYFUNCTION("""COMPUTED_VALUE"""),"0865 447 575") -> 0865 447 575 | B28: =IFERROR(__xludf.DUMMYFUNCTION("""COMPUTED_VALUE"""),"anh phan bá Đức") -> anh phan bá Đức | C28: =IFERROR(__xludf.DUMMYFUNCTION("""COMPUTED_VALUE"""),"29 hẻm 2 k44 lê ngô cát") -> 29 hẻm 2 k44 lê ngô cát | D28: =IFERROR(__xludf.DUMMYFUNCTION("""COMPUTED_VALUE"""),"chó") -> chó
A29: =IFERROR(__xludf.DUMMYFUNCTION("""COMPUTED_VALUE"""),"0386 164 608") -> 0386 164 608 | B29: =IFERROR(__xludf.DUMMYFUNCTION("""COMPUTED_VALUE"""),"Em Thiện Tâm") -> Em Thiện Tâm | C29: =IFERROR(__xludf.DUMMYFUNCTION("""COMPUTED_VALUE"""),"83k131 Trần Phú") -> 83k131 Trần Phú | D29: =IFERROR(__xludf.DUMMYFUNCTION("""COMPUTED_VALUE"""),"mèo") -> mèo | E29: =IFERROR(__xludf.DUMMYFUNCTION("""COMPUTED_VALUE"""),"bảnh") -> bảnh
A30: =IFERROR(__xludf.DUMMYFUNCTION("""COMPUTED_VALUE"""),"0374 558 914") -> 0374 558 914 | B30: =IFERROR(__xludf.DUMMYFUNCTION("""COMPUTED_VALUE"""),"Em Uyên Phương") -> Em Uyên Phương | C30: =IFERROR(__xludf.DUMMYFUNCTION("""COMPUTED_VALUE"""),"16 Dương Xuân Hạ") -> 16 Dương Xuân Hạ | D30: =IFERROR(__xludf.DUMMYFUNCTION("""COMPUTED_VALUE"""),"mèo") -> mèo | E30: =IFERROR(__xludf.DUMMYFUNCTION("""COMPUTED_VALUE"""),"mèo") -> mèo
A31: =IFERROR(__xludf.DUMMYFUNCTION("""COMPUTED_VALUE"""),"0837 052 752") -> 0837 052 752 | B31: =IFERROR(__xludf.DUMMYFUNCTION("""COMPUTED_VALUE"""),"em Quỳnh") -> em Quỳnh | C31: =IFERROR(__xludf.DUMMYFUNCTION("""COMPUTED_VALUE"""),"9c k131 Trần Phú") -> 9c k131 Trần Phú | D31: =IFERROR(__xludf.DUMMYFUNCTION("""COMPUTED_VALUE"""),"mèo") -> mèo | E31: =IFERROR(__xludf.DUMMYFUNCTION("""COMPUTED_VALUE"""),"tèo") -> tèo
A32: =IFERROR(__xludf.DUMMYFUNCTION("""COMPUTED_VALUE"""),"0932 412 231") -> 0932 412 231 | B32: =IFERROR(__xludf.DUMMYFUNCTION("""COMPUTED_VALUE"""),"Anh Huy") -> Anh Huy | C32: =IFERROR(__xludf.DUMMYFUNCTION("""COMPUTED_VALUE"""),"đh kinh tế huế") -> đh kinh tế huế | D32: =IFERROR(__xludf.DUMMYFUNCTION("""COMPUTED_VALUE"""),"chó") -> chó | E32: =IFERROR(__xludf.DUMMYFUNCTION("""COMPUTED_VALUE"""),"lượm") -> lượm
A33: =IFERROR(__xludf.DUMMYFUNCTION("""COMPUTED_VALUE"""),"0941 658 067") -> 0941 658 067 | B33: =IFERROR(__xludf.DUMMYFUNCTION("""COMPUTED_VALUE"""),"chị Lê Trang Nguyên") -> chị Lê Trang Nguyên | C33: =IFERROR(__xludf.DUMMYFUNCTION("""COMPUTED_VALUE"""),"52 Hàm Nghi") -> 52 Hàm Nghi | D33: =IFERROR(__xludf.DUMMYFUNCTION("""COMPUTED_VALUE"""),"chó") -> chó | E33: =IFERROR(__xludf.DUMMYFUNCTION("""COMPUTED_VALUE"""),"mỡ") -> mỡ
A34: =IFERROR(__xludf.DUMMYFUNCTION("""COMPUTED_VALUE"""),"0776 907 777") -> 0776 907 777 | B34: =IFERROR(__xludf.DUMMYFUNCTION("""COMPUTED_VALUE"""),"Chị Thủy") -> Chị Thủy | C34: =IFERROR(__xludf.DUMMYFUNCTION("""COMPUTED_VALUE"""),"117 Lương Nhữ hộc") -> 117 Lương Nhữ hộc | D34: =IFERROR(__xludf.DUMMYFUNCTION("""COMPUTED_VALUE"""),"mèo ") -> mèo
A35: =IFERROR(__xludf.DUMMYFUNCTION("""COMPUTED_VALUE"""),"0794 185 492") -> 0794 185 492 | B35: =IFERROR(__xludf.DUMMYFUNCTION("""COMPUTED_VALUE"""),"em Kim Anh") -> em Kim Anh | C35: =IFERROR(__xludf.DUMMYFUNCTION("""COMPUTED_VALUE"""),"Thiên Thai") -> Thiên Thai | D35: =IFERROR(__xludf.DUMMYFUNCTION("""COMPUTED_VALUE"""),"chó") -> chó | E35: =IFERROR(__xludf.DUMMYFUNCTION("""COMPUTED_VALUE"""),"bu bu") -> bu bu
A36: =IFERROR(__xludf.DUMMYFUNCTION("""COMPUTED_VALUE"""),"0914 614 253") -> 0914 614 253 | B36: =IFERROR(__xludf.DUMMYFUNCTION("""COMPUTED_VALUE"""),"Dì Kim Soa") -> Dì Kim Soa | C36: =IFERROR(__xludf.DUMMYFUNCTION("""COMPUTED_VALUE"""),"52a lê công hành") -> 52a lê công hành | D36: =IFERROR(__xludf.DUMMYFUNCTION("""COMPUTED_VALUE"""),"mèo") -> mèo
A37: =IFERROR(__xludf.DUMMYFUNCTION("""COMPUTED_VALUE"""),"0763 697 522") -> 0763 697 522 | B37: =IFERROR(__xludf.DUMMYFUNCTION("""COMPUTED_VALUE"""),"em Xuân Vy") -> em Xuân Vy | C37: =IFERROR(__xludf.DUMMYFUNCTION("""COMPUTED_VALUE"""),"32/69 Đặng Huy Trứ") -> 32/69 Đặng Huy Trứ | D37: =IFERROR(__xludf.DUMMYFUNCTION("""COMPUTED_VALUE"""),"mèo") -> mèo
A38: =IFERROR(__xludf.DUMMYFUNCTION("""COMPUTED_VALUE"""),"0394 533 206") -> 0394 533 206 | B38: =IFERROR(__xludf.DUMMYFUNCTION("""COMPUTED_VALUE"""),"Em Quang") -> Em Quang | C38: =IFERROR(__xludf.DUMMYFUNCTION("""COMPUTED_VALUE"""),"43/69/131 Trần Phú") -> 43/69/131 Trần Phú | D38: =IFERROR(__xludf.DUMMYFUNCTION("""COMPUTED_VALUE"""),"chó") -> chó | E38: =IFERROR(__xludf.DUMMYFUNCTION("""COMPUTED_VALUE"""),"mích") -> mích
A39: =IFERROR(__xludf.DUMMYFUNCTION("""COMPUTED_VALUE"""),"0836 133 468") -> 0836 133 468 | B39: =IFERROR(__xludf.DUMMYFUNCTION("""COMPUTED_VALUE"""),"Chị Khánh") -> Chị Khánh | C39: =IFERROR(__xludf.DUMMYFUNCTION("""COMPUTED_VALUE"""),"thích tịnh khiết") -> thích tịnh khiết | D39: =IFERROR(__xludf.DUMMYFUNCTION("""COMPUTED_VALUE"""),"chó") -> chó | E39: =IFERROR(__xludf.DUMMYFUNCTION("""COMPUTED_VALUE"""),"mỡ") -> mỡ
A40: =IFERROR(__xludf.DUMMYFUNCTION("""COMPUTED_VALUE"""),"0948 699 208") -> 0948 699 208 | B40: =IFERROR(__xludf.DUMMYFUNCTION("""COMPUTED_VALUE"""),"Chú Nguyễn Thu") -> Chú Nguyễn Thu | C40: =IFERROR(__xludf.DUMMYFUNCTION("""COMPUTED_VALUE"""),"29 Trần Đại Nghĩa -An Cựu") -> 29 Trần Đại Nghĩa -An Cựu | D40: =IFERROR(__xludf.DUMMYFUNCTION("""COMPUTED_VALUE"""),"chó") -> chó | E40: =IFERROR(__xludf.DUMMYFUNCTION("""COMPUTED_VALUE"""),"bi") -> bi
A41: =IFERROR(__xludf.DUMMYFUNCTION("""COMPUTED_VALUE"""),"0827 879 356") -> 0827 879 356 | B41: =IFERROR(__xludf.DUMMYFUNCTION("""COMPUTED_VALUE"""),"Cô Liên vợ Thầy Hải") -> Cô Liên vợ Thầy Hải | C41: =IFERROR(__xludf.DUMMYFUNCTION("""COMPUTED_VALUE"""),"Hương Hồ") -> Hương Hồ | D41: =IFERROR(__xludf.DUMMYFUNCTION("""COMPUTED_VALUE"""),"mèo") -> mèo
...

Sheet Danh muc Chi
C1: Chi hỗn hợp | E1: =G1-I1 -> 6498.5 | F1: Tổng | G1: =sum(G3:G226) -> 11202.5 | H1: Chi lưu kho | I1: =SUMIFS(G3:G596, F3:F596, "Thuoc dieu tri") + SUMIFS(G3:G596, F3:F596, "Vat tu") + SUMIFS(G3:G596, F3:F596, "Vaccine") -> 4704 | J1: =sum(J3:J226) -> 11202.5
A2: Ngày | B2: Nội dung | C2: Số lượng | D2: Đơn vị tính | E2: Đơn giá | F2: Thuộc hạng mục | G2: Số tiền | H2: Người chi | I2: Chú ý | J2: Tổng chi theo tuần/tháng
A3: 45965 | B3: Xăng xe Tuấn | C3: 1 | D3: lần | E3: 50 | F3: Xăng xe ca | G3: =C3*E3 -> 50 | H3: Tuấn
B4: giấy vs | C4: 2 | D4: lốc | E4: 40 | F4: Chi khac | G4: =C4*E4 -> 80 | H4: Trà
B5: tiền điện | C5: 1 | D5: hóa đơn | E5: 2308 | F5: Tien dien | G5: =C5*E5 -> 2308 | H5: Ánh
B6: internet | C6: 1 | D6: hóa đơn | E6: 195 | F6: Internet | G6: =C6*E6 -> 195 | H6: Ánh
A7: 45966 | B7: gan, phổi | C7: 5 | D7: kg | E7: 20 | F7: Thuc an cho thu luu tru | G7: =C7*E7 -> 100 | H7: Ánh
B8: hộp nhựa | C8: 1 | D8: bao | E8: 65 | F8: Hỏa táng | G8: =C8*E8 -> 65 | H8: Trà
A9: Tuần 1 | G9: =C9*E9 -> 0 | J9: =sum(G3:G8) -> 2798
A10: 45971 | B10: xn phong châu | C10: 1 | D10: hóa đơn | E10: 144 | F10: Xet nghiem | G10: =C10*E10 -> 144 | H10: Ánh
B11: gan, phổi | C11: 1 | D11: túi | E11: 140 | F11: Thuc an cho thu luu tru | G11: =C11*E11 -> 140 | H11: Ánh
B12: gạo | C12: 10 | D12: kg | E12: 14 | F12: Thuc an cho thu luu tru | G12: =C12*E12 -> 140 | H12: Ánh
B13: nhận hàng thầy | C13: 1 | D13: lần | E13: 35 | F13: Hàng của thầy | G13: =C13*E13 -> 35 | H13: Ánh
A14: 45972 | B14: xn phong châu | C14: 1 | D14: hóa đơn | E14: 48 | F14: Xet nghiem | G14: =C14*E14 -> 48 | H14: Ánh
B15: cephalexin | C15: 1 | D15: hộp | E15: 105 | F15: Thuoc dieu tri | G15: =C15*E15 -> 105 | H15: Ánh
B16: boganic | C16: 1 | D16: hộp | E16: 80 | F16: Thuoc dieu tri | G16: =C16*E16 -> 80 | H16: Ánh
B17: jasunny | C17: 1 | D17: hộp | E17: 315 | F17: Thuoc dieu tri | G17: =C17*E17 -> 315 | H17: Ánh
B18: men th | C18: 5 | D18: hộp | E18: 15 | F18: Thuoc dieu tri | G18: =C18*E18 -> 75 | H18: Ánh
B19: metro | C19: 1 | D19: hộp | E19: 27 | F19: Thuoc dieu tri | G19: =C19*E19 -> 27 | H19: Ánh
B20: vtm c | C20: 2 | D20: hộp | E20: 28 | F20: Thuoc dieu tri | G20: =C20*E20 -> 56 | H20: Ánh
B21: smecta | C21: 2 | D21: hộp | E21: 46 | F21: Thuoc dieu tri | G21: =C21*E21 -> 92 | H21: Ánh
B22: xylanh 3cc | C22: 2 | D22: hộp | E22: 62 | F22: Vat tu | G22: =C22*E22 -> 124 | H22: Ánh
B23: nước muối rửa | C23: 5 | D23: chai | E23: 5 | F23: Vat tu | G23: =C23*E23 -> 25 | H23: Ánh
A24: 45974 | B24: pate lon meo | C24: 1 | D24: lon | E24: 39.5 | F24: Thuc an cho thu luu tru | G24: =C24*E24 -> 39.5 | H24: Trà
B25: sữa bi-o | C25: 1 | D25: gói | E25: 26.5 | F25: Thuc an cho thu luu tru | G25: =C25*E25 -> 26.5 | H25: Trà
A26: 45976 | B26: gan, phổi | C26: 1 | D26: túi | E26: 140 | F26: Thuc an cho thu luu tru | G26: =C26*E26 -> 140 | H26: Tuấn
B27: pate lon mèo | C27: 1 | D27: lon | E27: 39.5 | F27: Thuc an cho thu luu tru | G27: =C27*E27 -> 39.5 | H27: Ánh
A28: 45977 | B28: xăng xe trà | C28: 1 | D28: lần | E28: 50 | F28: Xăng xe ca | G28: =C28*E28 -> 50 | H28: Trà
B29: hoa hỏa táng | C29: 1 | D29: bó | E29: 30 | F29: Hỏa táng | G29: =C29*E29 -> 30 | H29: Trà
A30: Tuần 2 | G30: =C30*E30 -> 0 | J30: =sum(G10:G29) -> 1731.5
A31: 45979 | B31: gạo | C31: 1 | D31: bao | E31: 100 | F31: Thuc an cho thu luu tru | G31: =C31*E31 -> 100 | H31: Trà
B32: nhận hàng thầy | C32: 1 | D32: lần | E32: 1092 | F32: Hàng của thầy | G32: =C32*E32 -> 1092 | H32: Ánh
B33: xăng xe Ánh | C33: 1 | D33: lần | E33: 30 | F33: Xăng xe ca | G33: =C33*E33 -> 30 | H33: Ánh
B34: men vi sinh | C34: 5 | D34: hộp | E34: =455/5 -> 91 | F34: Thuoc dieu tri | G34: =C34*E34 -> 455 | H34: Ánh
B35: gas | C35: 1 | D35: bình | E35: 390 | F35: Tien gas | G35: =C35*E35 -> 390 | H35: Ánh
B36: nước rửa chén | C36: 1 | D36: túi | E36: 32 | F36: Hoa chat | G36: =C36*E36 -> 32 | H36: Ánh
B37: hộp | C37: 1 | D37: bao | E37: 40 | F37: Vat tu | G37: =C37*E37 -> 40 | H37: Trà
B38: gan phổi | C38: 1 | D38: túi | E38: 90 | F38: Thuc an cho thu luu tru | G38: =C38*E38 -> 90 | H38: Ánh
B39: doxy | C39: 2 | D39: hộp | E39: 75 | F39: Thuoc dieu tri | G39: =C39*E39 -> 150 | H39: Ánh
B40: pred | C40: 2 | D40: hộp | E40: 55 | F40: Thuoc dieu tri | G40: =C40*E40 -> 110 | H40: Ánh
...

Sheet Can doi thu chi
B1: Can doi thu chi | E1: Petshop
B2: Thu | C2: Chi tuần | D2: đã nhận | E2: Doanh thu tháng | F2: 6887196
A3: Tuần 1 | B3: ='BC Thang'!Q91 -> 25820 | C3: ='Danh muc Chi'!J9 -> 2798 | E3: Doanh thu thuần | F3: 6887196
A4: Tuần 2 | B4: ='BC Thang'!Q174 -> 42242 | C4: ='Danh muc Chi'!J30 -> 1731.5 | E4: Giá vốn | F4: 4535810
A5: Tuần 3 | B5: ='BC Thang'!Q298 -> 29855 | C5: ='Danh muc Chi'!J45 -> 3139 | E5: Lợi nhuận | F5: =F2-F4 -> 2351386
A6: Tuần 4 | B6: ='BC Thang'!Q428 -> 24313 | C6: ='Danh muc Chi'!J75 -> 3534 | F6: Thu petshop | G6: Chi petshop (xuất chuyển cơ sở)
A7: chuyển khoản petshop(báo cáo) | B7: =SuMIFS('BC Thang'!M4:M2974,'BC Thang'!N4:N2974,"CK petshop Thầy") -> 2816 | C7: ='Danh muc Chi'!J117 | E7: Tổng | F7: 6887 | G7: ='Chi petshop'!G1 -> 0
A8: Tổng | B8: =SUM(B3:B6)-B7 -> 119414 | C8: =SUM(C3:C7) -> 11202.5 | D8: =sum(D3:D6) -> 0 | E8: Chuyển khoản thầy (Petshop) | G8: =SuMIFS('BC Thang'!M4:M2974,'BC Thang'!N4:N2974,"CK petshop Thầy") -> 2816
A9: Thầy chi | B9: =SUMIFS('Danh muc Chi'!G3:G807,'Danh muc Chi'!H3:H807,"Thầy") -> 700 | E9: Tổng gửi thầy petshop | F9: =F7-G8 -> 4071
A10: Thầy nhận trực tiếp | C10: =SuMIFS('BC Thang'!M4:M2974,'BC Thang'!N4:N2974,"Thầy") -> 60
A11: Chuyển khoản thầy (khám chữa bệnh) | C11: =SuMIFS('BC Thang'!M4:M2974,'BC Thang'!N4:N2974,"CK Thầy") -> 95550
A13: Tiền nhà
A14: Tổng gửi thầy báo cáo | B14: =(B8+B9-C8-C10-C11-C13) -> 13301.5
A15: Gửi thầy cuối tháng Báo cáo + petshop | B15: =B14+F9 -> 17372.5 | C15: Chenh lech | D15: =C25-B15 -> -11.5
A16: 500 | B16: 17 | C16: =A16*B16 -> 8500
A17: 200 | B17: 13 | C17: =A17*B17 -> 2600
A18: 100 | B18: 57 | C18: =A18*B18 -> 5700
A19: 50 | B19: 11 | C19: =A19*B19 -> 550
A20: 20 | C20: =A20*B20 -> 0
A21: 10 | B21: 1 | C21: =A21*B21 -> 10
A22: 5 | C22: =A22*B22 -> 0
A23: 2 | C23: =A23*B23 -> 0
A24: 1 | B24: 1 | C24: =A24*B24 -> 1
A25: Nhận tiền mặt | B25: =SUM(B16:B24) -> 100 | C25: =sum(C16:C24) -> 17361

Sheet Chi petshop
G1: =sum(G3:G60) -> 0
A2: Ngày | B2: Nội dung petshop | C2: Số lượng | D2: Đơn vị tính | E2: Đơn giá | F2: Thuộc hạng mục | G2: Số tiền | H2: Người chi | I2: Chú ý | J2: Tổng chi theo tuần/tháng
F3: Petshop | G3: =C3*E3 -> 0
F4: Petshop | G4: =C4*E4 -> 0
F5: Petshop | G5: =C5*E5 -> 0
F6: Petshop | G6: =C6*E6 -> 0
F7: Petshop | G7: =C7*E7 -> 0
F8: Petshop | G8: =C8*E8 -> 0
F9: Petshop | G9: =C9*E9 -> 0
F10: Petshop | G10: =C10*E10 -> 0
F11: Petshop | G11: =C11*E11 -> 0
F12: Petshop | G12: =C12*E12 -> 0
F13: Petshop | G13: =C13*E13 -> 0
F14: Petshop | G14: =C14*E14 -> 0
... F948: Petshop | G948: =C948*E948 -> 0

Sheet BC Vat Tu
E1: SL Tồn đầu tháng | F1: =sum(F3:F333) -> 89110302 | G1: Nhập | L1: =sum(L3:L300) -> 3350466.7 | N1: Xuất chuyển CS | R1: =sum(R3:R300) -> 0 | T1: Tổng | U1: =sum(U3:U223) -> 15726210 | V1: =sum(V3:V310) -> 76734558
A2: =IFERROR(__xludf.DUMMYFUNCTION("importrange(""https://docs.google.com/spreadsheets/d/1ImCdkYhsUqsakZA8jNZp7UrWFPNTrMyfZQst-0aGkKM/edit#gid=510873834"",""Ma hang!A1:D500"")"),"Mã Hàng") -> Mã Hàng | B2: =IFERROR(__xludf.DUMMYFUNCTION("""COMPUTED_VALUE"""),"Tên hàng") -> Tên hàng | C2: =IFERROR(__xludf.DUMMYFUNCTION("""COMPUTED_VALUE"""),"Đơn vị Tính") -> Đơn vị Tính | D2: =IFERROR(__xludf.DUMMYFUNCTION("""COMPUTED_VALUE"""),"Giá nhập TB") -> Giá nhập TB | E2: 45962 | F2: Tiền tồn đầu tháng | G2: Tuần 1 | H2: Tuần 2 | I2: Tuần 3 | J2: Tuần 4 | K2: Tổng SL Nhập | L2: Tổng tiền nhập | M2: Tuần 1 | N2: Tuần 2 | O2: Tuần 3 | P2: Tuần 4 | Q2: Tổng SL Xuất | R2: Tổng tiền xuất | S2: Kiêm kê (tồn cuối) | T2: SL SD trong tháng | U2: Tiền SD trong tháng | V2: Số tiền tồn cuối
A3: =IFERROR(__xludf.DUMMYFUNCTION("""COMPUTED_VALUE"""),"APC") -> APC | B3: =IFERROR(__xludf.DUMMYFUNCTION("""COMPUTED_VALUE"""),"A chymotrypsin") -> A chymotrypsin | C3: =IFERROR(__xludf.DUMMYFUNCTION("""COMPUTED_VALUE"""),"Viên") -> Viên | D3: =IFERROR(__xludf.DUMMYFUNCTION("""COMPUTED_VALUE"""),250.0) -> 250 | E3: 435 | F3: =E3*$D3 -> 108750 | K3: =G3+H3+I3+J3 -> 0 | L3: =K3*$D3 -> 0 | Q3: =M3+N3+O3+P3 -> 0 | R3: =Q3*$D3 -> 0 | S3: =220+100+22 -> 342 | T3: =E3+K3-Q3-S3 -> 93 | U3: =T3*D3 -> 23250 | V3: =S3*$D3 -> 85500
A4: =IFERROR(__xludf.DUMMYFUNCTION("""COMPUTED_VALUE"""),"ACV") -> ACV | B4: =IFERROR(__xludf.DUMMYFUNCTION("""COMPUTED_VALUE"""),"Acyclovir 200") -> Acyclovir 200 | C4: =IFERROR(__xludf.DUMMYFUNCTION("""COMPUTED_VALUE"""),"Viên") -> Viên | D4: =IFERROR(__xludf.DUMMYFUNCTION("""COMPUTED_VALUE"""),2414.285714285714) -> 2414.2857 | E4: 34 | F4: =E4*$D4 -> 82085.714 | K4: =G4+H4+I4+J4 -> 0 | L4: =K4*$D4 -> 0 | Q4: =M4+N4+O4+P4 -> 0 | R4: =Q4*$D4 -> 0 | S4: 34 | T4: =E4+K4-Q4-S4 -> 0 | U4: =T4*D4 -> 0 | V4: =S4*$D4 -> 82085.714
A5: =IFERROR(__xludf.DUMMYFUNCTION("""COMPUTED_VALUE"""),"ADEVTM") -> ADEVTM | B5: =IFERROR(__xludf.DUMMYFUNCTION("""COMPUTED_VALUE"""),"AD3E Vitamin") -> AD3E Vitamin | C5: =IFERROR(__xludf.DUMMYFUNCTION("""COMPUTED_VALUE"""),"mL") -> mL | D5: =IFERROR(__xludf.DUMMYFUNCTION("""COMPUTED_VALUE"""),1400.0) -> 1400 | E5: 150 | F5: =E5*$D5 -> 210000 | K5: =G5+H5+I5+J5 -> 0 | L5: =K5*$D5 -> 0 | Q5: =M5+N5+O5+P5 -> 0 | R5: =Q5*$D5 -> 0 | S5: 150 | T5: =E5+K5-Q5-S5 -> 0 | U5: =T5*D5 -> 0 | V5: =S5*$D5 -> 210000
A6: =IFERROR(__xludf.DUMMYFUNCTION("""COMPUTED_VALUE"""),"TKADL") -> TKADL | B6: =IFERROR(__xludf.DUMMYFUNCTION("""COMPUTED_VALUE"""),"Adrenalin") -> Adrenalin | C6: =IFERROR(__xludf.DUMMYFUNCTION("""COMPUTED_VALUE"""),"Ống") -> Ống | D6: =IFERROR(__xludf.DUMMYFUNCTION("""COMPUTED_VALUE"""),3000.0) -> 3000 | E6: 61 | F6: =E6*$D6 -> 183000 | K6: =G6+H6+I6+J6 -> 0 | L6: =K6*$D6 -> 0 | Q6: =M6+N6+O6+P6 -> 0 | R6: =Q6*$D6 -> 0 | S6: 0 | T6: =E6+K6-Q6-S6 -> 61 | U6: =T6*D6 -> 183000 | V6: =S6*$D6 -> 0
A7: =IFERROR(__xludf.DUMMYFUNCTION("""COMPUTED_VALUE"""),"AMVTM") -> AMVTM | B7: =IFERROR(__xludf.DUMMYFUNCTION("""COMPUTED_VALUE"""),"Aminovit") -> Aminovit | C7: =IFERROR(__xludf.DUMMYFUNCTION("""COMPUTED_VALUE"""),"mL") -> mL | D7: =IFERROR(__xludf.DUMMYFUNCTION("""COMPUTED_VALUE"""),300.0) -> 300 | E7: 0 | F7: =E7*$D7 -> 0 | K7: =G7+H7+I7+J7 -> 0 | L7: =K7*$D7 -> 0 | Q7: =M7+N7+O7+P7 -> 0 | R7: =Q7*$D7 -> 0 | S7: 0 | T7: =E7+K7-Q7-S7 -> 0 | U7: =T7*D7 -> 0 | V7: =S7*$D7 -> 0
A8: =IFERROR(__xludf.DUMMYFUNCTION("""COMPUTED_VALUE"""),"AMOX") -> AMOX | B8: =IFERROR(__xludf.DUMMYFUNCTION("""COMPUTED_VALUE"""),"Amoxicilin 250ml") -> Amoxicilin 250ml | C8: =IFERROR(__xludf.DUMMYFUNCTION("""COMPUTED_VALUE"""),"mL") -> mL | D8: =IFERROR(__xludf.DUMMYFUNCTION("""COMPUTED_VALUE"""),0.0) -> 0 | E8: 50 | F8: =E8*$D8 -> 0 | K8: =G8+H8+I8+J8 -> 0 | L8: =K8*$D8 -> 0 | Q8: =M8+N8+O8+P8 -> 0 | R8: =Q8*$D8 -> 0 | S8: 50 | T8: =E8+K8-Q8-S8 -> 0 | U8: =T8*D8 -> 0 | V8: =S8*$D8 -> 0
A9: =IFERROR(__xludf.DUMMYFUNCTION("""COMPUTED_VALUE"""),"ATD") -> ATD | B9: =IFERROR(__xludf.DUMMYFUNCTION("""COMPUTED_VALUE"""),"Antiderm bôi ghẻ") -> Antiderm bôi ghẻ | C9: =IFERROR(__xludf.DUMMYFUNCTION("""COMPUTED_VALUE"""),"Tuýp") -> Tuýp | D9: =IFERROR(__xludf.DUMMYFUNCTION("""COMPUTED_VALUE"""),35000.0) -> 35000 | E9: 0 | F9: =E9*$D9 -> 0 | K9: =G9+H9+I9+J9 -> 0 | L9: =K9*$D9 -> 0 | Q9: =M9+N9+O9+P9 -> 0 | R9: =Q9*$D9 -> 0 | S9: 0 | T9: =E9+K9-Q9-S9 -> 0 | U9: =T9*D9 -> 0 | V9: =S9*$D9 -> 0
A10: =IFERROR(__xludf.DUMMYFUNCTION("""COMPUTED_VALUE"""),"APT") -> APT | B10: =IFERROR(__xludf.DUMMYFUNCTION("""COMPUTED_VALUE"""),"Áo phẫu thuật") -> Áo phẫu thuật | C10: =IFERROR(__xludf.DUMMYFUNCTION("""COMPUTED_VALUE"""),"Cái") -> Cái | D10: =IFERROR(__xludf.DUMMYFUNCTION("""COMPUTED_VALUE"""),300000.0) -> 300000 | E10: 54 | F10: =E10*$D10 -> 16200000 | K10: =G10+H10+I10+J10 -> 0 | L10: =K10*$D10 -> 0 | Q10: =M10+N10+O10+P10 -> 0 | R10: =Q10*$D10 -> 0 | S10: 50 | T10: =E10+K10-Q10-S10 -> 4 | U10: =T10*D10 -> 1200000 | V10: =S10*$D10 -> 15000000
A11: =IFERROR(__xludf.DUMMYFUNCTION("""COMPUTED_VALUE"""),"ATP") -> ATP | B11: =IFERROR(__xludf.DUMMYFUNCTION("""COMPUTED_VALUE"""),"Atropin") -> Atropin | C11: =IFERROR(__xludf.DUMMYFUNCTION("""COMPUTED_VALUE"""),"mL") -> mL | D11: =IFERROR(__xludf.DUMMYFUNCTION("""COMPUTED_VALUE"""),163.33333333333334) -> 163.33333 | E11: 168 | F11: =E11*$D11 -> 27440 | J11: 200 | K11: =G11+H11+I11+J11 -> 200 | L11: =K11*$D11 -> 32666.667 | Q11: =M11+N11+O11+P11 -> 0 | R11: =Q11*$D11 -> 0 | S11: =200+58+85 -> 343 | T11: =E11+K11-Q11-S11 -> 25 | U11: =T11*D11 -> 4083.3333 | V11: =S11*$D11 -> 56023.333
A12: =IFERROR(__xludf.DUMMYFUNCTION("""COMPUTED_VALUE"""),"AZT") -> AZT | B12: =IFERROR(__xludf.DUMMYFUNCTION("""COMPUTED_VALUE"""),"Azithromycin ") -> Azithromycin | C12: =IFERROR(__xludf.DUMMYFUNCTION("""COMPUTED_VALUE"""),"Gam") -> Gam | D12: =IFERROR(__xludf.DUMMYFUNCTION("""COMPUTED_VALUE"""),20000.0) -> 20000 | E12: 25 | F12: =E12*$D12 -> 500000 | K12: =G12+H12+I12+J12 -> 0 | L12: =K12*$D12 -> 0 | Q12: =M12+N12+O12+P12 -> 0 | R12: =Q12*$D12 -> 0 | S12: 25 | T12: =E12+K12-Q12-S12 -> 0 | U12: =T12*D12 -> 0 | V12: =S12*$D12 -> 500000
A13: =IFERROR(__xludf.DUMMYFUNCTION("""COMPUTED_VALUE"""),"AZT250") -> AZT250 | B13: =IFERROR(__xludf.DUMMYFUNCTION("""COMPUTED_VALUE"""),"Azithromycin 250mg") -> Azithromycin 250mg | C13: =IFERROR(__xludf.DUMMYFUNCTION("""COMPUTED_VALUE"""),"Viên") -> Viên | D13: =IFERROR(__xludf.DUMMYFUNCTION("""COMPUTED_VALUE"""),1950.0) -> 1950 | E13: 6 | F13: =E13*$D13 -> 11700 | K13: =G13+H13+I13+J13 -> 0 | L13: =K13*$D13 -> 0 | Q13: =M13+N13+O13+P13 -> 0 | R13: =Q13*$D13 -> 0 | S13: 6 | T13: =E13+K13-Q13-S13 -> 0 | U13: =T13*D13 -> 0 | V13: =S13*$D13 -> 11700
A14: =IFERROR(__xludf.DUMMYFUNCTION("""COMPUTED_VALUE"""),"AZT500") -> AZT500 | B14: =IFERROR(__xludf.DUMMYFUNCTION("""COMPUTED_VALUE"""),"Azithromycin 500mg") -> Azithromycin 500mg | C14: =IFERROR(__xludf.DUMMYFUNCTION("""COMPUTED_VALUE"""),"Viên") -> Viên | D14: =IFERROR(__xludf.DUMMYFUNCTION("""COMPUTED_VALUE"""),4683.166666666666) -> 4683.1667 | E14: 2 | F14: =E14*$D14 -> 9366.3333 | K14: =G14+H14+I14+J14 -> 0 | L14: =K14*$D14 -> 0 | Q14: =M14+N14+O14+P14 -> 0 | R14: =Q14*$D14 -> 0 | S14: 2 | T14: =E14+K14-Q14-S14 -> 0 | U14: =T14*D14 -> 0 | V14: =S14*$D14 -> 9366.3333
A15: =IFERROR(__xludf.DUMMYFUNCTION("""COMPUTED_VALUE"""),"BCL") -> BCL | B15: =IFERROR(__xludf.DUMMYFUNCTION("""COMPUTED_VALUE"""),"B complex") -> B complex | C15: =IFERROR(__xludf.DUMMYFUNCTION("""COMPUTED_VALUE"""),"ml") -> ml | D15: =IFERROR(__xludf.DUMMYFUNCTION("""COMPUTED_VALUE"""),300.0) -> 300 | E15: 160 | F15: =E15*$D15 -> 48000 | K15: =G15+H15+I15+J15 -> 0 | L15: =K15*$D15 -> 0 | Q15: =M15+N15+O15+P15 -> 0 | R15: =Q15*$D15 -> 0 | S15: 160 | T15: =E15+K15-Q15-S15 -> 0 | U15: =T15*D15 -> 0 | V15: =S15*$D15 -> 48000
A16: =IFERROR(__xludf.DUMMYFUNCTION("""COMPUTED_VALUE"""),"BCRT") -> BCRT | B16: =IFERROR(__xludf.DUMMYFUNCTION("""COMPUTED_VALUE"""),"Bàn chải rửa tay") -> Bàn chải rửa tay | C16: =IFERROR(__xludf.DUMMYFUNCTION("""COMPUTED_VALUE"""),"Cái") -> Cái | D16: =IFERROR(__xludf.DUMMYFUNCTION("""COMPUTED_VALUE"""),38000.0) -> 38000 | E16: 0 | F16: =E16*$D16 -> 0 | K16: =G16+H16+I16+J16 -> 0 | L16: =K16*$D16 -> 0 | Q16: =M16+N16+O16+P16 -> 0 | R16: =Q16*$D16 -> 0 | S16: 0 | T16: =E16+K16-Q16-S16 -> 0 | U16: =T16*D16 -> 0 | V16: =S16*$D16 -> 0
A17: =IFERROR(__xludf.DUMMYFUNCTION("""COMPUTED_VALUE"""),"BIOGTT") -> BIOGTT | B17: =IFERROR(__xludf.DUMMYFUNCTION("""COMPUTED_VALUE"""),"BIO Genta-Tylosin") -> BIO Genta-Tylosin | C17: =IFERROR(__xludf.DUMMYFUNCTION("""COMPUTED_VALUE"""),"mL") -> mL | D17: =IFERROR(__xludf.DUMMYFUNCTION("""COMPUTED_VALUE"""),1100.0) -> 1100 | E17: 71 | F17: =E17*$D17 -> 78100 | K17: =G17+H17+I17+J17 -> 0 | L17: =K17*$D17 -> 0 | Q17: =M17+N17+O17+P17 -> 0 | R17: =Q17*$D17 -> 0 | S17: 60 | T17: =E17+K17-Q17-S17 -> 11 | U17: =T17*D17 -> 12100 | V17: =S17*$D17 -> 66000
A18: =IFERROR(__xludf.DUMMYFUNCTION("""COMPUTED_VALUE"""),"OCTC") -> OCTC | B18: =IFERROR(__xludf.DUMMYFUNCTION("""COMPUTED_VALUE"""),"BIO Oxytocin") -> BIO Oxytocin | C18: =IFERROR(__xludf.DUMMYFUNCTION("""COMPUTED_VALUE"""),"mL") -> mL | D18: =IFERROR(__xludf.DUMMYFUNCTION("""COMPUTED_VALUE"""),600.0) -> 600 | E18: 40 | F18: =E18*$D18 -> 24000 | K18: =G18+H18+I18+J18 -> 0 | L18: =K18*$D18 -> 0 | Q18: =M18+N18+O18+P18 -> 0 | R18: =Q18*$D18 -> 0 | S18: 40 | T18: =E18+K18-Q18-S18 -> 0 | U18: =T18*D18 -> 0 | V18: =S18*$D18 -> 24000
A19: =IFERROR(__xludf.DUMMYFUNCTION("""COMPUTED_VALUE"""),"BS") -> BS | B19: =IFERROR(__xludf.DUMMYFUNCTION("""COMPUTED_VALUE"""),"BIO sone") -> BIO sone | C19: =IFERROR(__xludf.DUMMYFUNCTION("""COMPUTED_VALUE"""),"mL") -> mL | D19: =IFERROR(__xludf.DUMMYFUNCTION("""COMPUTED_VALUE"""),1300.0) -> 1300 | E19: 120 | F19: =E19*$D19 -> 156000 | K19: =G19+H19+I19+J19 -> 0 | L19: =K19*$D19 -> 0 | Q19: =M19+N19+O19+P19 -> 0 | R19: =Q19*$D19 -> 0 | S19: 120 | T19: =E19+K19-Q19-S19 -> 0 | U19: =T19*D19 -> 0 | V19: =S19*$D19 -> 156000
A20: =IFERROR(__xludf.DUMMYFUNCTION("""COMPUTED_VALUE"""),"VTMB12T") -> VTMB12T | B20: =IFERROR(__xludf.DUMMYFUNCTION("""COMPUTED_VALUE"""),"BIO-FER+B12") -> BIO-FER+B12 | C20: =IFERROR(__xludf.DUMMYFUNCTION("""COMPUTED_VALUE"""),"mL") -> mL | D20: =IFERROR(__xludf.DUMMYFUNCTION("""COMPUTED_VALUE"""),500.0) -> 500 | E20: 68 | F20: =E20*$D20 -> 34000 | K20: =G20+H20+I20+J20 -> 0 | L20: =K20*$D20 -> 0 | Q20: =M20+N20+O20+P20 -> 0 | R20: =Q20*$D20 -> 0 | S20: 60 | T20: =E20+K20-Q20-S20 -> 8 | U20: =T20*D20 -> 4000 | V20: =S20*$D20 -> 30000
A21: =IFERROR(__xludf.DUMMYFUNCTION("""COMPUTED_VALUE"""),"BTC") -> BTC | B21: =IFERROR(__xludf.DUMMYFUNCTION("""COMPUTED_VALUE"""),"Bột thạch cao") -> Bột thạch cao | C21: =IFERROR(__xludf.DUMMYFUNCTION("""COMPUTED_VALUE"""),"cuộn") -> cuộn | D21: =IFERROR(__xludf.DUMMYFUNCTION("""COMPUTED_VALUE"""),15000.0) -> 15000 | E21: 4 | F21: =E21*$D21 -> 60000 | K21: =G21+H21+I21+J21 -> 0 | L21: =K21*$D21 -> 0 | Q21: =M21+N21+O21+P21 -> 0 | R21: =Q21*$D21 -> 0 | S21: 4 | T21: =E21+K21-Q21-S21 -> 0 | U21: =T21*D21 -> 0 | V21: =S21*$D21 -> 60000
A22: =IFERROR(__xludf.DUMMYFUNCTION("""COMPUTED_VALUE"""),"BHXT") -> BHXT | B22: =IFERROR(__xludf.DUMMYFUNCTION("""COMPUTED_VALUE"""),"Bromhexine tiêm") -> Bromhexine tiêm | C22: =IFERROR(__xludf.DUMMYFUNCTION("""COMPUTED_VALUE"""),"mL") -> mL | D22: =IFERROR(__xludf.DUMMYFUNCTION("""COMPUTED_VALUE"""),1000.0) -> 1000 | E22: 140 | F22: =E22*$D22 -> 140000 | K22: =G22+H22+I22+J22 -> 0 | L22: =K22*$D22 -> 0 | Q22: =M22+N22+O22+P22 -> 0 | R22: =Q22*$D22 -> 0 | S22: 140 | T22: =E22+K22-Q22-S22 -> 0 | U22: =T22*D22 -> 0 | V22: =S22*$D22 -> 140000
A23: =IFERROR(__xludf.DUMMYFUNCTION("""COMPUTED_VALUE"""),"BHXU") -> BHXU | B23: =IFERROR(__xludf.DUMMYFUNCTION("""COMPUTED_VALUE"""),"Bromhexine uống") -> Bromhexine uống | C23: =IFERROR(__xludf.DUMMYFUNCTION("""COMPUTED_VALUE"""),"Viên") -> Viên | D23: =IFERROR(__xludf.DUMMYFUNCTION("""COMPUTED_VALUE"""),180.0) -> 180 | E23: 193 | F23: =E23*$D23 -> 34740 | K23: =G23+H23+I23+J23 -> 0 | L23: =K23*$D23 -> 0 | Q23: =M23+N23+O23+P23 -> 0 | R23: =Q23*$D23 -> 0 | S23: =136+49 -> 185 | T23: =E23+K23-Q23-S23 -> 8 | U23: =T23*D23 -> 1440 | V23: =S23*$D23 -> 33300
A24: =IFERROR(__xludf.DUMMYFUNCTION("""COMPUTED_VALUE"""),"CX") -> CX | B24: =IFERROR(__xludf.DUMMYFUNCTION("""COMPUTED_VALUE"""),"Canxi") -> Canxi | C24: =IFERROR(__xludf.DUMMYFUNCTION("""COMPUTED_VALUE"""),"Viên") -> Viên | D24: =IFERROR(__xludf.DUMMYFUNCTION("""COMPUTED_VALUE"""),230.0) -> 230 | E24: 13 | F24: =E24*$D24 -> 2990 | K24: =G24+H24+I24+J24 -> 0 | L24: =K24*$D24 -> 0 | Q24: =M24+N24+O24+P24 -> 0 | R24: =Q24*$D24 -> 0 | S24: 6 | T24: =E24+K24-Q24-S24 -> 7 | U24: =T24*D24 -> 1610 | V24: =S24*$D24 -> 1380
A25: =IFERROR(__xludf.DUMMYFUNCTION("""COMPUTED_VALUE"""),"CXT") -> CXT | B25: =IFERROR(__xludf.DUMMYFUNCTION("""COMPUTED_VALUE"""),"Canxi tiêm") -> Canxi tiêm | C25: =IFERROR(__xludf.DUMMYFUNCTION("""COMPUTED_VALUE"""),"mL") -> mL | D25: =IFERROR(__xludf.DUMMYFUNCTION("""COMPUTED_VALUE"""),425.0) -> 425 | E25: 25 | F25: =E25*$D25 -> 10625 | K25: =G25+H25+I25+J25 -> 0 | L25: =K25*$D25 -> 0 | Q25: =M25+N25+O25+P25 -> 0 | R25: =Q25*$D25 -> 0 | S25: 13 | T25: =E25+K25-Q25-S25 -> 12 | U25: =T25*D25 -> 5100 | V25: =S25*$D25 -> 5525
A26: =IFERROR(__xludf.DUMMYFUNCTION("""COMPUTED_VALUE"""),"CSTAN") -> CSTAN | B26: =IFERROR(__xludf.DUMMYFUNCTION("""COMPUTED_VALUE"""),"CasTran an thần") -> CasTran an thần | C26: =IFERROR(__xludf.DUMMYFUNCTION("""COMPUTED_VALUE"""),"mL") -> mL | D26: =IFERROR(__xludf.DUMMYFUNCTION("""COMPUTED_VALUE"""),1200.0) -> 1200 | E26: 0 | F26: =E26*$D26 -> 0 | K26: =G26+H26+I26+J26 -> 0 | L26: =K26*$D26 -> 0 | Q26: =M26+N26+O26+P26 -> 0 | R26: =Q26*$D26 -> 0 | S26: 0 | T26: =E26+K26-Q26-S26 -> 0 | U26: =T26*D26 -> 0 | V26: =S26*$D26 -> 0
A27: =IFERROR(__xludf.DUMMYFUNCTION("""COMPUTED_VALUE"""),"CTZ") -> CTZ | B27: =IFERROR(__xludf.DUMMYFUNCTION("""COMPUTED_VALUE"""),"Ceftriazone_Cefuroxim (KS pha tiêm)") -> Ceftriazone_Cefuroxim (KS pha tiêm) | C27: =IFERROR(__xludf.DUMMYFUNCTION("""COMPUTED_VALUE"""),"Gam") -> Gam | D27: =IFERROR(__xludf.DUMMYFUNCTION("""COMPUTED_VALUE"""),20000.0) -> 20000 | E27: 0 | F27: =E27*$D27 -> 0 | K27: =G27+H27+I27+J27 -> 0 | L27: =K27*$D27 -> 0 | Q27: =M27+N27+O27+P27 -> 0 | R27: =Q27*$D27 -> 0 | S27: 0 | T27: =E27+K27-Q27-S27 -> 0 | U27: =T27*D27 -> 0 | V27: =S27*$D27 -> 0
A28: =IFERROR(__xludf.DUMMYFUNCTION("""COMPUTED_VALUE"""),"CF500") -> CF500 | B28: =IFERROR(__xludf.DUMMYFUNCTION("""COMPUTED_VALUE"""),"Cephalexin 500") -> Cephalexin 500 | C28: =IFERROR(__xludf.DUMMYFUNCTION("""COMPUTED_VALUE"""),"Viên") -> Viên | D28: =IFERROR(__xludf.DUMMYFUNCTION("""COMPUTED_VALUE"""),1200.0) -> 1200 | E28: 184 | F28: =E28*$D28 -> 220800 | H28: 100 | K28: =G28+H28+I28+J28 -> 100 | L28: =K28*$D28 -> 120000 | Q28: =M28+N28+O28+P28 -> 0 | R28: =Q28*$D28 -> 0 | S28: 100 | T28: =E28+K28-Q28-S28 -> 184 | U28: =T28*D28 -> 220800 | V28: =S28*$D28 -> 120000
A29: =IFERROR(__xludf.DUMMYFUNCTION("""COMPUTED_VALUE"""),"CTRZ") -> CTRZ | B29: =IFERROR(__xludf.DUMMYFUNCTION("""COMPUTED_VALUE"""),"Cetirizin") -> Cetirizin | C29: =IFERROR(__xludf.DUMMYFUNCTION("""COMPUTED_VALUE"""),"Viên") -> Viên | D29: =IFERROR(__xludf.DUMMYFUNCTION("""COMPUTED_VALUE"""),200.0) -> 200 | E29: 85 | F29: =E29*$D29 -> 17000 | K29: =G29+H29+I29+J29 -> 0 | L29: =K29*$D29 -> 0 | Q29: =M29+N29+O29+P29 -> 0 | R29: =Q29*$D29 -> 0 | S29: 85 | T29: =E29+K29-Q29-S29 -> 0 | U29: =T29*D29 -> 0 | V29: =S29*$D29 -> 17000
A30: =IFERROR(__xludf.DUMMYFUNCTION("""COMPUTED_VALUE"""),"CDTT") -> CDTT | B30: =IFERROR(__xludf.DUMMYFUNCTION("""COMPUTED_VALUE"""),"Chai đựng thuốc tắm") -> Chai đựng thuốc tắm | C30: =IFERROR(__xludf.DUMMYFUNCTION("""COMPUTED_VALUE"""),"Chai") -> Chai | D30: =IFERROR(__xludf.DUMMYFUNCTION("""COMPUTED_VALUE"""),1200.0) -> 1200 | E30: 29 | F30: =E30*$D30 -> 34800 | K30: =G30+H30+I30+J30 -> 0 | L30: =K30*$D30 -> 0 | Q30: =M30+N30+O30+P30 -> 0 | R30: =Q30*$D30 -> 0 | S30: 15 | T30: =E30+K30-Q30-S30 -> 14 | U30: =T30*D30 -> 16800 | V30: =S30*$D30 -> 18000
A31: =IFERROR(__xludf.DUMMYFUNCTION("""COMPUTED_VALUE"""),"CKCG2/0") -> CKCG2/0 | B31: =IFERROR(__xludf.DUMMYFUNCTION("""COMPUTED_VALUE"""),"Chỉ catgut 2/0") -> Chỉ catgut 2/0 | C31: =IFERROR(__xludf.DUMMYFUNCTION("""COMPUTED_VALUE"""),"Sợi") -> Sợi | D31: =IFERROR(__xludf.DUMMYFUNCTION("""COMPUTED_VALUE"""),10000.0) -> 10000 | E31: 0 | F31: =E31*$D31 -> 0 | K31: =G31+H31+I31+J31 -> 0 | L31: =K31*$D31 -> 0 | Q31: =M31+N31+O31+P31 -> 0 | R31: =Q31*$D31 -> 0 | S31: 0 | T31: =E31+K31-Q31-S31 -> 0 | U31: =T31*D31 -> 0 | V31: =S31*$D31 -> 0
A32: =IFERROR(__xludf.DUMMYFUNCTION("""COMPUTED_VALUE"""),"CKCG3/0") -> CKCG3/0 | B32: =IFERROR(__xludf.DUMMYFUNCTION("""COMPUTED_VALUE"""),"Chỉ catgut 3/0") -> Chỉ catgut 3/0 | C32: =IFERROR(__xludf.DUMMYFUNCTION("""COMPUTED_VALUE"""),"Sợi") -> Sợi | D32: =IFERROR(__xludf.DUMMYFUNCTION("""COMPUTED_VALUE"""),10000.0) -> 10000 | E32: 0 | F32: =E32*$D32 -> 0 | K32: =G32+H32+I32+J32 -> 0 | L32: =K32*$D32 -> 0 | Q32: =M32+N32+O32+P32 -> 0 | R32: =Q32*$D32 -> 0 | S32: 0 | T32: =E32+K32-Q32-S32 -> 0 | U32: =T32*D32 -> 0 | V32: =S32*$D32 -> 0
A33: =IFERROR(__xludf.DUMMYFUNCTION("""COMPUTED_VALUE"""),"CKCG4/0") -> CKCG4/0 | B33: =IFERROR(__xludf.DUMMYFUNCTION("""COMPUTED_VALUE"""),"Chỉ catgut 4/0") -> Chỉ catgut 4/0 | C33: =IFERROR(__xludf.DUMMYFUNCTION("""COMPUTED_VALUE"""),"Sợi") -> Sợi | D33: =IFERROR(__xludf.DUMMYFUNCTION("""COMPUTED_VALUE"""),10000.0) -> 10000 | E33: 0 | F33: =E33*$D33 -> 0 | K33: =G33+H33+I33+J33 -> 0 | L33: =K33*$D33 -> 0 | Q33: =M33+N33+O33+P33 -> 0 | R33: =Q33*$D33 -> 0 | S33: 0 | T33: =E33+K33-Q33-S33 -> 0 | U33: =T33*D33 -> 0 | V33: =S33*$D33 -> 0
A34: =IFERROR(__xludf.DUMMYFUNCTION("""COMPUTED_VALUE"""),"CKCGKK") -> CKCGKK | B34: =IFERROR(__xludf.DUMMYFUNCTION("""COMPUTED_VALUE"""),"Chỉ catgut không kim") -> Chỉ catgut không kim | C34: =IFERROR(__xludf.DUMMYFUNCTION("""COMPUTED_VALUE"""),"Sợi") -> Sợi | D34: =IFERROR(__xludf.DUMMYFUNCTION("""COMPUTED_VALUE"""),2000.0) -> 2000 | E34: 0 | F34: =E34*$D34 -> 0 | K34: =G34+H34+I34+J34 -> 0 | L34: =K34*$D34 -> 0 | Q34: =M34+N34+O34+P34 -> 0 | R34: =Q34*$D34 -> 0 | S34: 0 | T34: =E34+K34-Q34-S34 -> 0 | U34: =T34*D34 -> 0 | V34: =S34*$D34 -> 0
A35: =IFERROR(__xludf.DUMMYFUNCTION("""COMPUTED_VALUE"""),"CKKTD") -> CKKTD | B35: =IFERROR(__xludf.DUMMYFUNCTION("""COMPUTED_VALUE"""),"Chỉ khâu không tiêu dù") -> Chỉ khâu không tiêu dù | C35: =IFERROR(__xludf.DUMMYFUNCTION("""COMPUTED_VALUE"""),"Mét") -> Mét | D35: =IFERROR(__xludf.DUMMYFUNCTION("""COMPUTED_VALUE"""),600.0) -> 600 | E35: 0 | F35: =E35*$D35 -> 0 | K35: =G35+H35+I35+J35 -> 0 | L35: =K35*$D35 -> 0 | Q35: =M35+N35+O35+P35 -> 0 | R35: =Q35*$D35 -> 0 | S35: 0 | T35: =E35+K35-Q35-S35 -> 0 | U35: =T35*D35 -> 0 | V35: =S35*$D35 -> 0
A36: =IFERROR(__xludf.DUMMYFUNCTION("""COMPUTED_VALUE"""),"VCRKK3/0") -> VCRKK3/0 | B36: =IFERROR(__xludf.DUMMYFUNCTION("""COMPUTED_VALUE"""),"Chỉ khâu Vicryl không kim 3/0") -> Chỉ khâu Vicryl không kim 3/0 | C36: =IFERROR(__xludf.DUMMYFUNCTION("""COMPUTED_VALUE"""),"Sợi") -> Sợi | D36: =IFERROR(__xludf.DUMMYFUNCTION("""COMPUTED_VALUE"""),4875.0) -> 4875 | E36: 0 | F36: =E36*$D36 -> 0 | K36: =G36+H36+I36+J36 -> 0 | L36: =K36*$D36 -> 0 | Q36: =M36+N36+O36+P36 -> 0 | R36: =Q36*$D36 -> 0 | S36: 0 | T36: =E36+K36-Q36-S36 -> 0 | U36: =T36*D36 -> 0 | V36: =S36*$D36 -> 0
A37: =IFERROR(__xludf.DUMMYFUNCTION("""COMPUTED_VALUE"""),"CKKT3/0KK") -> CKKT3/0KK | B37: =IFERROR(__xludf.DUMMYFUNCTION("""COMPUTED_VALUE"""),"Chỉ không tiêu 3/0 không kim") -> Chỉ không tiêu 3/0 không kim | C37: =IFERROR(__xludf.DUMMYFUNCTION("""COMPUTED_VALUE"""),"Sợi") -> Sợi | D37: =IFERROR(__xludf.DUMMYFUNCTION("""COMPUTED_VALUE"""),2000.0) -> 2000 | E37: 0 | F37: =E37*$D37 -> 0 | K37: =G37+H37+I37+J37 -> 0 | L37: =K37*$D37 -> 0 | Q37: =M37+N37+O37+P37 -> 0 | R37: =Q37*$D37 -> 0 | S37: 0 | T37: =E37+K37-Q37-S37 -> 0 | U37: =T37*D37 -> 0 | V37: =S37*$D37 -> 0
A38: =IFERROR(__xludf.DUMMYFUNCTION("""COMPUTED_VALUE"""),"CKNL10/0") -> CKNL10/0 | B38: =IFERROR(__xludf.DUMMYFUNCTION("""COMPUTED_VALUE"""),"Chỉ nilon 10/0") -> Chỉ nilon 10/0 | C38: =IFERROR(__xludf.DUMMYFUNCTION("""COMPUTED_VALUE"""),"Sợi") -> Sợi | D38: =IFERROR(__xludf.DUMMYFUNCTION("""COMPUTED_VALUE"""),60000.0) -> 60000 | E38: 0 | F38: =E38*$D38 -> 0 | K38: =G38+H38+I38+J38 -> 0 | L38: =K38*$D38 -> 0 | Q38: =M38+N38+O38+P38 -> 0 | R38: =Q38*$D38 -> 0 | S38: 0 | T38: =E38+K38-Q38-S38 -> 0 | U38: =T38*D38 -> 0 | V38: =S38*$D38 -> 0
A39: =IFERROR(__xludf.DUMMYFUNCTION("""COMPUTED_VALUE"""),"CKNL2/0") -> CKNL2/0 | B39: =IFERROR(__xludf.DUMMYFUNCTION("""COMPUTED_VALUE"""),"Chỉ nilon 2/0") -> Chỉ nilon 2/0 | C39: =IFERROR(__xludf.DUMMYFUNCTION("""COMPUTED_VALUE"""),"Sợi") -> Sợi | D39: =IFERROR(__xludf.DUMMYFUNCTION("""COMPUTED_VALUE"""),10000.0) -> 10000 | E39: 6 | F39: =E39*$D39 -> 60000 | K39: =G39+H39+I39+J39 -> 0 | L39: =K39*$D39 -> 0 | Q39: =M39+N39+O39+P39 -> 0 | R39: =Q39*$D39 -> 0 | S39: 6 | T39: =E39+K39-Q39-S39 -> 0 | U39: =T39*D39 -> 0 | V39: =S39*$D39 -> 60000
A40: =IFERROR(__xludf.DUMMYFUNCTION("""COMPUTED_VALUE"""),"CKNL3/0") -> CKNL3/0 | B40: =IFERROR(__xludf.DUMMYFUNCTION("""COMPUTED_VALUE"""),"Chỉ nilon 3/0") -> Chỉ nilon 3/0 | C40: =IFERROR(__xludf.DUMMYFUNCTION("""COMPUTED_VALUE"""),"Sợi") -> Sợi | D40: =IFERROR(__xludf.DUMMYFUNCTION("""COMPUTED_VALUE"""),10000.0) -> 10000 | E40: 0 | F40: =E40*$D40 -> 0 | K40: =G40+H40+I40+J40 -> 0 | L40: =K40*$D40 -> 0 | Q40: =M40+N40+O40+P40 -> 0 | R40: =Q40*$D40 -> 0 | S40: 0 | T40: =E40+K40-Q40-S40 -> 0 | U40: =T40*D40 -> 0 | V40: =S40*$D40 -> 0
...

Sheet Hang muc chi
A1: =IFERROR(__xludf.DUMMYFUNCTION("importrange(""https://docs.google.com/spreadsheets/d/1ImCdkYhsUqsakZA8jNZp7UrWFPNTrMyfZQst-0aGkKM/edit#gid=0"",""Hang muc chi!A1:D25"")"),"Hạng mục chi") -> Hạng mục chi | B1: =IFERROR(__xludf.DUMMYFUNCTION("""COMPUTED_VALUE"""),"Người chi") -> Người chi | C1: =IFERROR(__xludf.DUMMYFUNCTION("""COMPUTED_VALUE"""),"Người Thu") -> Người Thu | D1: =IFERROR(__xludf.DUMMYFUNCTION("""COMPUTED_VALUE"""),"Loài") -> Loài
A2: =IFERROR(__xludf.DUMMYFUNCTION("""COMPUTED_VALUE"""),"Xet nghiem") -> Xet nghiem | B2: =IFERROR(__xludf.DUMMYFUNCTION("""COMPUTED_VALUE"""),"Đức") -> Đức | C2: =IFERROR(__xludf.DUMMYFUNCTION("""COMPUTED_VALUE"""),"Đức") -> Đức | D2: =IFERROR(__xludf.DUMMYFUNCTION("""COMPUTED_VALUE"""),"Chó") -> Chó
A3: =IFERROR(__xludf.DUMMYFUNCTION("""COMPUTED_VALUE"""),"Thuoc dieu tri") -> Thuoc dieu tri | B3: =IFERROR(__xludf.DUMMYFUNCTION("""COMPUTED_VALUE"""),"Tuyến") -> Tuyến | C3: =IFERROR(__xludf.DUMMYFUNCTION("""COMPUTED_VALUE"""),"Tuyến") -> Tuyến | D3: =IFERROR(__xludf.DUMMYFUNCTION("""COMPUTED_VALUE"""),"Mèo") -> Mèo
A4: =IFERROR(__xludf.DUMMYFUNCTION("""COMPUTED_VALUE"""),"Vat tu") -> Vat tu | B4: =IFERROR(__xludf.DUMMYFUNCTION("""COMPUTED_VALUE"""),"Nhung") -> Nhung | C4: =IFERROR(__xludf.DUMMYFUNCTION("""COMPUTED_VALUE"""),"Thầy") -> Thầy | D4: =IFERROR(__xludf.DUMMYFUNCTION("""COMPUTED_VALUE"""),"Thỏ") -> Thỏ
A5: =IFERROR(__xludf.DUMMYFUNCTION("""COMPUTED_VALUE"""),"Tien an") -> Tien an | B5: =IFERROR(__xludf.DUMMYFUNCTION("""COMPUTED_VALUE"""),"Thầy") -> Thầy | C5: =IFERROR(__xludf.DUMMYFUNCTION("""COMPUTED_VALUE"""),"Linh") -> Linh | D5: =IFERROR(__xludf.DUMMYFUNCTION("""COMPUTED_VALUE"""),"Gà") -> Gà
A6: =IFERROR(__xludf.DUMMYFUNCTION("""COMPUTED_VALUE"""),"Thuc an cho thu luu tru") -> Thuc an cho thu luu tru | B6: =IFERROR(__xludf.DUMMYFUNCTION("""COMPUTED_VALUE"""),"Linh") -> Linh | C6: =IFERROR(__xludf.DUMMYFUNCTION("""COMPUTED_VALUE"""),"K Trang") -> K Trang | D6: =IFERROR(__xludf.DUMMYFUNCTION("""COMPUTED_VALUE"""),"Chuột") -> Chuột
A7: =IFERROR(__xludf.DUMMYFUNCTION("""COMPUTED_VALUE"""),"Card dien thoai") -> Card dien thoai | B7: =IFERROR(__xludf.DUMMYFUNCTION("""COMPUTED_VALUE"""),"K Trang") -> K Trang | C7: =IFERROR(__xludf.DUMMYFUNCTION("""COMPUTED_VALUE"""),"CK thầy") -> CK thầy | D7: =IFERROR(__xludf.DUMMYFUNCTION("""COMPUTED_VALUE"""),"Bò sát") -> Bò sát
A8: =IFERROR(__xludf.DUMMYFUNCTION("""COMPUTED_VALUE"""),"Bao tri, thay the") -> Bao tri, thay the | B8: =IFERROR(__xludf.DUMMYFUNCTION("""COMPUTED_VALUE"""),"H Trang") -> H Trang | C8: =IFERROR(__xludf.DUMMYFUNCTION("""COMPUTED_VALUE"""),"CK petshop thầy") -> CK petshop thầy | D8: =IFERROR(__xludf.DUMMYFUNCTION("""COMPUTED_VALUE"""),"Khỉ") -> Khỉ
A9: =IFERROR(__xludf.DUMMYFUNCTION("""COMPUTED_VALUE"""),"Hoa chat") -> Hoa chat | B9: =IFERROR(__xludf.DUMMYFUNCTION("""COMPUTED_VALUE"""),"Hiến") -> Hiến | C9: =IFERROR(__xludf.DUMMYFUNCTION("""COMPUTED_VALUE"""),"Nhung") -> Nhung | D9: =IFERROR(__xludf.DUMMYFUNCTION("""COMPUTED_VALUE"""),"Chim") -> Chim
A10: =IFERROR(__xludf.DUMMYFUNCTION("""COMPUTED_VALUE"""),"Internet") -> Internet | B10: =IFERROR(__xludf.DUMMYFUNCTION("""COMPUTED_VALUE"""),"Lý") -> Lý | C10: =IFERROR(__xludf.DUMMYFUNCTION("""COMPUTED_VALUE"""),"H Trang") -> H Trang
A11: =IFERROR(__xludf.DUMMYFUNCTION("""COMPUTED_VALUE"""),"Vaccine") -> Vaccine | B11: =IFERROR(__xludf.DUMMYFUNCTION("""COMPUTED_VALUE"""),"Tiến") -> Tiến | C11: =IFERROR(__xludf.DUMMYFUNCTION("""COMPUTED_VALUE"""),"Hiến") -> Hiến
A12: =IFERROR(__xludf.DUMMYFUNCTION("""COMPUTED_VALUE"""),"Chi khac") -> Chi khac | B12: =IFERROR(__xludf.DUMMYFUNCTION("""COMPUTED_VALUE"""),"Hải") -> Hải | C12: =IFERROR(__xludf.DUMMYFUNCTION("""COMPUTED_VALUE"""),"Lý") -> Lý
A13: =IFERROR(__xludf.DUMMYFUNCTION("""COMPUTED_VALUE"""),"Tien dien") -> Tien dien | B13: =IFERROR(__xludf.DUMMYFUNCTION("""COMPUTED_VALUE"""),"Khang") -> Khang | C13: =IFERROR(__xludf.DUMMYFUNCTION("""COMPUTED_VALUE"""),"Lam") -> Lam
A14: =IFERROR(__xludf.DUMMYFUNCTION("""COMPUTED_VALUE"""),"Tien nuoc") -> Tien nuoc | B14: =IFERROR(__xludf.DUMMYFUNCTION("""COMPUTED_VALUE"""),"Ánh") -> Ánh | C14: =IFERROR(__xludf.DUMMYFUNCTION("""COMPUTED_VALUE"""),"HV") -> HV
A15: =IFERROR(__xludf.DUMMYFUNCTION("""COMPUTED_VALUE"""),"Tien gas") -> Tien gas | B15: =IFERROR(__xludf.DUMMYFUNCTION("""COMPUTED_VALUE"""),"Trà") -> Trà | C15: =IFERROR(__xludf.DUMMYFUNCTION("""COMPUTED_VALUE"""),"Hải") -> Hải
A16: =IFERROR(__xludf.DUMMYFUNCTION("""COMPUTED_VALUE"""),"Máy trợ thở") -> Máy trợ thở | B16: =IFERROR(__xludf.DUMMYFUNCTION("""COMPUTED_VALUE"""),"Tuấn") -> Tuấn | C16: =IFERROR(__xludf.DUMMYFUNCTION("""COMPUTED_VALUE"""),"Khang") -> Khang
A17: =IFERROR(__xludf.DUMMYFUNCTION("""COMPUTED_VALUE"""),"Hỏa táng") -> Hỏa táng | C17: =IFERROR(__xludf.DUMMYFUNCTION("""COMPUTED_VALUE"""),"Ánh") -> Ánh
